Workbook
Name \0: #REF!
Name \0: #REF!
Name \0: #REF!
Name \0: #REF!
Name \0: #REF!
Name \0: #REF!
Name \0: #REF!
Name \0: #REF!
Name \1: #REF!
Name \1: #REF!
Name \1: #REF!
Name \1: #REF!
Name \1: #REF!
Name \1: #REF!
Name \1: #REF!
Name \1: #REF!
Name \a: #REF!
Name \a: #REF!
Name \a: #REF!
Name \a: #REF!
Name \a: #REF!
Name \a: #REF!
Name \a: #REF!
Name \a: #REF!
Name \a: #REF!
Name \a: #REF!
Name \b: #REF!
Name \b: #REF!
Name \b: #REF!
Name \b: #REF!
Name \b: #REF!
Name \b: #REF!
Name \b: #REF!
Name \b: #REF!
Name \b: #REF!
Name \b: #REF!
Name \b11_567891011: #REF!
Name \b11_567891011: #REF!
Name \b11_567891011: #REF!
Name \b11_567891011: #REF!
Name \b11_567891011: #REF!
Name \b11_567891011: #REF!
Name \b11_567891011: #REF!
Name \b12_567891011: #REF!
Name \b12_567891011: #REF!
Name \b12_567891011: #REF!
Name \b12_567891011: #REF!
Name \b12_567891011: #REF!
Name \b12_567891011: #REF!
Name \b12_567891011: #REF!
Name \b13_567891011: #REF!
Name \b13_567891011: #REF!
Name \b13_567891011: #REF!
Name \b13_567891011: #REF!
Name \b13_567891011: #REF!
Name \b13_567891011: #REF!
Name \b13_567891011: #REF!
Name \b14_567891011: #REF!
Name \b14_567891011: #REF!
Name \b14_567891011: #REF!

Sheet RANK
B2: ="NILAI KINERJA UP3 TOLITOLI S.D "&[0]!A&" 2023" -> #REF!
B4: RANK | C4: UNIT | D4: ="NKO S.D "&[0]!A -> #REF!
B5: 1 | C5: =VLOOKUP(B5,$G$5:$I$9,2,FALSE) -> ULP BANGKIR | D5: =VLOOKUP(B5,$G$5:$I$9,3,FALSE) -> 105.5 | G5: =RANK(I5,$I$5:$I$9) -> 5 | H5: ULP TOLITOLI | I5: =ULP!L58 -> 98.94
B6: 2 | C6: =VLOOKUP(B6,$G$5:$I$9,2,FALSE) -> ULP KOTARAYA | D6: =VLOOKUP(B6,$G$5:$I$9,3,FALSE) -> 103.42 | G6: =RANK(I6,$I$5:$I$9) -> 4 | H6: ULP LEOK | I6: =ULP!W58 -> 99.73
B7: 3 | C7: =VLOOKUP(B7,$G$5:$I$9,2,FALSE) -> ULP MOUTONG | D7: =VLOOKUP(B7,$G$5:$I$9,3,FALSE) -> 99.85 | G7: =RANK(I7,$I$5:$I$9) -> 1 | H7: ULP BANGKIR | I7: =ULP!AH58 -> 105.5
B8: 4 | C8: =VLOOKUP(B8,$G$5:$I$9,2,FALSE) -> ULP LEOK | D8: =VLOOKUP(B8,$G$5:$I$9,3,FALSE) -> 99.73 | G8: =RANK(I8,$I$5:$I$9) -> 3 | H8: ULP MOUTONG | I8: =ULP!AS58 -> 99.85
B9: 5 | C9: =VLOOKUP(B9,$G$5:$I$9,2,FALSE) -> ULP TOLITOLI | D9: =VLOOKUP(B9,$G$5:$I$9,3,FALSE) -> 98.94 | G9: =RANK(I9,$I$5:$I$9) -> 2 | H9: ULP KOTARAYA | I9: =ULP!BD58 -> 103.42
C10: UP3 TOLITOLI | D10: ='UP3'!J70 -> 102.84

Sheet CHECKLIST
B3: NO | C3: KPI | D3: ULP TOLITOLI | E3: ULP LEOK | F3: ULP BANGKIR | G3: ULP MOUTONG | H3: ULP KOTARAYA
C4: Key Performance Indicators
B5: 1 | C5: Penjualan dan Pendapatan Tenaga Listrik
C6: a. Penjualan Tenaga listrik | D6: =ULP!K11 -> 110 | E6: =ULP!V11 -> 110 | F6: =ULP!AG11 -> 110 | G6: =ULP!AR11 -> 110 | H6: =ULP!BC11 -> 110
C7: b. Pendapatan Penjualan Tenaga Listrik | D7: =ULP!K12 -> 110 | E7: =ULP!V12 -> 110 | F7: =ULP!AG12 -> 110 | G7: =ULP!AR12 -> 110 | H7: =ULP!BC12 -> 110
B8: 2 | C8: Pengendalian Piutang Rata-Rata Tunggakan | D8: =ULP!#REF! -> #REF! | E8: =ULP!#REF! -> #REF! | F8: =ULP!#REF! -> #REF! | G8: =ULP!#REF! -> #REF! | H8: =ULP!#REF! -> #REF!
B9: 3 | C9: Susut Jaringan (Tanpa E-Min) | D9: =ULP!#REF! -> #REF! | E9: =ULP!#REF! -> #REF! | F9: =ULP!#REF! -> #REF! | G9: =ULP!#REF! -> #REF! | H9: =ULP!#REF! -> #REF!
C10: Performance Indikator
B11: 4 | C11: Peningkatan Pelayanan
C12: a. Response Time Atas Keluhan | D12: =ULP!K21 -> 110 | E12: =ULP!V21 -> 110 | F12: =ULP!AG21 -> 110 | G12: =ULP!AR21 -> 110 | H12: =ULP!BC21 -> 110
C13: b. Recovery Time Atas Keluhan | D13: =ULP!K22 -> 110 | E13: =ULP!V22 -> 110 | F13: =ULP!AG22 -> 110 | G13: =ULP!AR22 -> 110 | H13: =ULP!BC22 -> 110
C14: c. Response Time Atas Gangguan | D14: =ULP!K23 -> 50 | E14: =ULP!V23 -> 110 | F14: =ULP!AG23 -> 110 | G14: =ULP!AR23 -> 110 | H14: =ULP!BC23 -> 110
C15: d. Recovery Time Atas Gangguan | D15: =ULP!K24 -> 107.5 | E15: =ULP!V24 -> 107.5 | F15: =ULP!AG24 -> 107.5 | G15: =ULP!AR24 -> 107.5 | H15: =ULP!BC24 -> 107.5
B16: 5 | C16: Jumlah Pengguna Aktif Aplikasi "PLN Mobile" | D16: =ULP!K26 -> 110 | E16: =ULP!V26 -> 110 | F16: =ULP!AG26 -> 110 | G16: =ULP!AR26 -> 110 | H16: =ULP!BC26 -> 110
B17: 6 | C17: Peningkatan Keandalan Jaringan
C18: a. SAIDI sesuai kewenangannya | D18: =ULP!K28 -> 110 | E18: =ULP!V28 -> 110 | F18: =ULP!AG28 -> 110 | G18: =ULP!AR28 -> 110 | H18: =ULP!BC28 -> 110
C19: b. SAIFI sesuai kewenangannya | D19: =ULP!K32 -> 110 | E19: =ULP!V32 -> 110 | F19: =ULP!AG32 -> 110 | G19: =ULP!AR32 -> 110 | H19: =ULP!BC32 -> 110
B20: 7 | C20: Percepatan Penyambungan Pelanggan
C21: - PB/PD Paskem TR Tanpa Perluasan Jaringan | D21: =ULP!K46 -> 100 | E21: =ULP!V46 -> 100 | F21: =ULP!AG46 -> 100 | G21: =ULP!AR46 -> 100 | H21: =ULP!BC46 -> 100
B22: 8 | C22: Organization Capital Readiness (OCR) | D22: =ULP!K48 -> 110 | E22: =ULP!V48 -> 110 | F22: =ULP!AG48 -> 110 | G22: =ULP!AR48 -> 78.485472 | H22: =ULP!BC48 -> 84.527461
B23: 9 | C23: Maturity Level Kepatuhan | D23: =ULP!#REF! -> #REF! | E23: =ULP!#REF! -> #REF! | F23: =ULP!#REF! -> #REF! | G23: =ULP!#REF! -> #REF! | H23: =ULP!#REF! -> #REF!
B24: 10 | C24: Pengelolaan Revenue Assurence
C25: a. Update Data Pelanggan | D25: =ULP!#REF! -> #REF! | E25: =ULP!#REF! -> #REF! | F25: =ULP!#REF! -> #REF! | G25: =ULP!#REF! -> #REF! | H25: =ULP!#REF! -> #REF!
C26: b. Migrasi VKRN 41 dan VKRN 42 | D26: =ULP!K49 -> 93.472631 | E26: =ULP!V49 -> 110 | F26: =ULP!AG49 -> 110 | G26: =ULP!AR49 -> 76.647386 | H26: =ULP!BC49 -> 68.506645
B27: 11 | C27: Migrasi LPB | D27: =ULP!K53 -> 0 | E27: =ULP!V53 -> 0 | F27: =ULP!AG53 -> 0 | G27: =ULP!AR53 -> 0 | H27: =ULP!BC53 -> 0
B28: 12 | C28: Eksekusi Program Peningkatan Keandalan dan Efisiensi Distribusi (NNC)
C29: a. Eksekusi Program Keandalan Distribusi | D29: =ULP!K56 -> 0 | E29: =ULP!V56 -> 0 | F29: =ULP!AG56 -> 0 | G29: =ULP!AR56 -> 0 | H29: =ULP!BC56 -> 0
C30: b. Eksekusi P2TL | D30: =ULP!#REF! -> #REF! | E30: =ULP!#REF! -> #REF! | F30: =ULP!#REF! -> #REF! | G30: =ULP!#REF! -> #REF! | H30: =ULP!#REF! -> #REF!
B31: 13 | C31: Kepatuhan
C32: a. Keselamatan Ketenagalistrikan
C33: b. Pengelolaan Lingkungan Hidup
C34: c. Ketepatan Penyampaian Laporan dan Akurasi Data Kinerja
C35: d.Pemenuhan TMP
B36: TOTAL PENILAIAN | D36: =ULP!L58 -> 98.94 | E36: =RANK!D6 -> 103.42 | F36: =ULP!AH58 -> 105.5 | G36: =ULP!AS58 -> 99.85 | H36: =ULP!BD58 -> 103.42

Sheet scoreboard
B2: KPI | C2: Target | D2: Real
A3: Key Performance Indicators
B4: Pertumbuhan Penjualan Tenaga Listrik | C4: ='UP3'!G9 -> 0 | D4: ='UP3'!H9 -> 0 | E4: =D4/C4 -> #DIV/0! | F4: =IF(E4>1,1,E4) -> #DIV/0! | G4: =1-F4 -> #DIV/0!
B5: Delta Daya Tersambung | C5: ='UP3'!G10 -> 233.89 | D5: ='UP3'!H10 -> 196.05712 | E5: =D5/C5 -> 0.83824498 | F5: =IF(E5>1,1,E5) -> 0.83824498 | G5: =1-F5 -> 0.16175502
B6: kWh Jual Multiguna Non Backfeeding | C6: ='UP3'!G17 -> 0 | D6: ='UP3'!H17 -> 0 | E6: =D6/C6 -> #DIV/0! | F6: =IF(E6>1,1,E6) -> #DIV/0! | G6: =1-F6 -> #DIV/0!
B7: Pertumbuhan Penjualan Layanan Khusus | C7: ='UP3'!#REF! -> #REF! | D7: ='UP3'!#REF! -> #REF! | E7: =D7/C7 -> #REF! | F7: =IF(E7>1,1,E7) -> #REF! | G7: =1-F7 -> #REF!
B8: Penambahan Pelanggan Premium | C8: ='UP3'!G18 -> 0 | D8: ='UP3'!H18 -> 0 | E8: =D8/C8 -> #DIV/0! | F8: =IF(E8>1,1,E8) -> #DIV/0! | G8: =1-F8 -> #DIV/0!
B9: Susut Jaringan (Tanpa E-Min) | C9: ='UP3'!G19 -> 148 | D9: ='UP3'!H19 -> 115 | E9: =2-(D9/C9) -> 1.222973 | F9: =IF(E9>1,1,E9) -> 1 | G9: =1-F9 -> 0
B10: SAIDI sesuai kewenangannya | C10: ='UP3'!G21 -> 5 | D10: ='UP3'!H21 -> 3 | E10: =2-(D10/C10) -> 1.4 | F10: =IF(E10>1,1,E10) -> 1 | G10: =1-F10 -> 0
B11: SAIFI sesuai kewenangannya | C11: ='UP3'!G22 -> 0 | D11: ='UP3'!H22 -> 0 | E11: =2-(D11/C11) -> #DIV/0! | F11: =IF(E11>1,1,E11) -> #DIV/0! | G11: =1-F11 -> #DIV/0!
B12: Energy Not Served | C12: ='UP3'!G24 -> 0.04 | D12: ='UP3'!H24 -> 0 | E12: =2-(D12/C12) -> 2 | F12: =IF(E12>1,1,E12) -> 1 | G12: =1-F12 -> 0
B13: Implementasi PLN Mobile | C13: ='UP3'!G25 -> 4.9 | D13: 100 | E13: =D13/C13 -> 20.408163 | F13: =IF(E13>1,1,E13) -> 1 | G13: =1-F13 -> 0
B14: Jumlah Komplain Pelanggan | C14: ='UP3'!#REF! -> #REF! | D14: ='UP3'!#REF! -> #REF! | E14: =D14/C14 -> #REF! | F14: 0 | G14: =1-F14 -> 1
B15: Aging Complaint | C15: ='UP3'!G33 -> 0 | D15: ='UP3'!H33 -> 0 | E15: =2-(D15/C15) -> #DIV/0! | F15: =IF(E15>1,1,E15) -> #DIV/0! | G15: =1-F15 -> #DIV/0!
B16: Rata-Rata Rasio Tunggakan | C16: ='UP3'!G38 -> 864 | D16: ='UP3'!H38 -> 939 | E16: =2-(D16/C16) -> 0.91319444 | F16: =IF(E16>1,1,E16) -> 0.91319444 | G16: =1-F16 -> 0.086805556
B17: Jumlah ULP NIHIL | C17: ='UP3'!G41 -> 21521.791 | D17: ='UP3'!H41 -> 74417.7 | E17: =D17/C17 -> 3.4577838 | F17: =IF(E17>1,1,E17) -> 1 | G17: =1-F17 -> 0
B18: Migrasi LPB pelanggan menunggak berulang | C18: ='UP3'!G42 -> 0 | D18: ='UP3'!H42 -> 0 | E18: =D18/C18 -> #DIV/0! | F18: =IF(E18>1,1,E18) -> #DIV/0! | G18: =1-F18 -> #DIV/0!
B19: BPP - Opex Non Fuel | C19: ='UP3'!G46 -> 1175 | D19: ='UP3'!H46 -> 1001.412 | E19: =2-(D19/C19) -> 1.1477345 | F19: =IF(E19>1,1,E19) -> 1 | G19: =1-F19 -> 0
B20: CF Pembangkit Non BBM | C20: ='UP3'!G50 -> 95-100 | D20: ='UP3'!H50 -> 90.3 | E20: =D20/C20 -> #VALUE! | F20: =IF(E20>1,1,E20) -> #VALUE! | G20: =1-F20 -> #VALUE!
B21: SFC PLTD PLN | C21: ='UP3'!G51 -> 0 | D21: ='UP3'!H51 -> 0 | E21: =2-(D21/C21) -> #DIV/0! | F21: =IF(E21>1,1,E21) -> #DIV/0! | G21: =1-F21 -> #DIV/0!
B22: ='UP3'!B53 -> Manajemen SDM, Komunikasi, dan TJSL | C22: ='UP3'!G53 -> 0 | D22: ='UP3'!H53 -> 0 | E22: =D22/C22 -> #DIV/0! | F22: =E22 -> #DIV/0! | G22: =1-F22 -> #DIV/0! | AO22: 264116
B23: ='UP3'!B55 -> b. Produktivitas Unit | C23: ='UP3'!G55 -> 100 | D23: ='UP3'!H55 -> 90 | E23: =D23/C23 -> 0.9 | F23: =IF(E23>1,1,E23) -> 0.9 | G23: =1-F23 -> 0.1 | AO23: =AO22-39 -> 264077
B24: ='UP3'!B56 -> c. Pengelolaan Komunikasi dan TJSL | C24: ='UP3'!G56 -> 100 | D24: ='UP3'!H56 -> 110 | E24: 100 | F24: =IF(E24>1,1,E24) -> 1 | G24: =1-F24 -> 0
B25: ='UP3'!B60 -> b. Maturity Level Gudang | C25: ='UP3'!G60 -> 3.65 | D25: ='UP3'!H60 -> 3.65 | E25: 100 | F25: =IF(E25>1,1,E25) -> 1 | G25: =1-F25 -> 0
B26: ='UP3'!B61 -> c. Maturity Level Sustainbility | C26: ='UP3'!G61 -> 100 | D26: ='UP3'!H61 -> 110 | E26: =D26/C26 -> 1.1 | F26: =IF(E26>1,1,E26) -> 1 | G26: =1-F26 -> 0
B27: ='UP3'!B62 -> d. Implementasi Roadmap Perbaikan Penerapan Manajemen Risiko dan Pencapaian Perlakuan Risiko | C27: ='UP3'!G62 -> 100 | D27: ='UP3'!H62 -> 100 | E27: =D27/C27 -> 1 | F27: =IF(E27>1,1,E27) -> 1 | G27: =1-F27 -> 0
B28: ='UP3'!B63 -> Kepatuhan : | C28: ='UP3'!G63 -> 0 | D28: ='UP3'!H63 -> 0 | E28: =D28/C28 -> #DIV/0! | F28: =IF(E28>1,1,E28) -> #DIV/0! | G28: =1-F28 -> #DIV/0!
B29: ='UP3'!B64 -> a. Pengelolaan K3, Keamanan dan Lingkungan Hidup | C29: ='UP3'!G64 -> 0 | D29: ='UP3'!H64 -> 0 | E29: 100 | F29: =IF(E29>1,1,E29) -> 1 | G29: =1-F29 -> 0
B30: ='UP3'!B66 -> c. Ketepatan penyampaian pelaporan dan Akurasi Data Kinerja | C30: ='UP3'!G66 -> 0 | D30: ='UP3'!H66 -> 0 | E30: 100 | F30: =IF(E30>1,1,E30) -> 1 | G30: =1-F30 -> 0
B39: SAIDI | C39: ='UP3'!G21 -> 5 | D39: ='UP3'!H21 -> 3 | E39: =2-(D39/C39) -> 1.4 | F39: =IF(E39>1,1,E39) -> 1 | G39: =1-F39 -> 0
B40: Rasio Tunggakan | C40: ='UP3'!G38 -> 864 | D40: ='UP3'!H38 -> 939 | E40: =2-(D40/C40) -> 0.91319444 | F40: =IF(E40>1,1,E40) -> 0.91319444 | G40: =1-F40 -> 0.086805556
B41: Multiguna | C41: ='UP3'!G17 -> 0 | D41: ='UP3'!H17 -> 0 | E41: =D41/C41 -> #DIV/0! | F41: =IF(E41>1,1,E41) -> #DIV/0! | G41: =1-F41 -> #DIV/0!
B42: RE 99 % | C42: ='UP3'!G55 -> 100 | D42: ='UP3'!H55 -> 90 | E42: =D42/C42 -> 0.9 | F42: =IF(E42>1,1,E42) -> 0.9 | G42: =1-F42 -> 0.1
B43: Komplain Pelanggan | C43: ='UP3'!#REF! -> #REF! | D43: ='UP3'!#REF! -> #REF! | E43: =D43/C43 -> #REF! | F43: 0 | G43: =1-F43 -> 1

Sheet TRACK
B2: Unit | C2: Nilai Kinerja Organisasi (NKO)
C3: Jan | D3: Feb | E3: Mar | F3: Apr | G3: May | H3: Jun | I3: Jul | J3: Aug | K3: Sep | L3: Oct | M3: Nov | N3: Dec
B4: ULP Tolitoli Khusus
B5: ULP Leok
B6: ULP Bangkir
B7: ULP Kotaraya
B8: UP3 Tolitoli | C8: =DETAIL!J43 -> #REF! | D8: =DETAIL!P43 -> #REF! | E8: =DETAIL!V43 -> #REF! | F8: =DETAIL!AB43 -> #N/A

Sheet DETAIL
B1: KONTRAK MANAJEMEN 2022
B2: PT PLN (PERSERO) UIW SULUTTENGGO
B3: UP3 TOLITOLI
A4: NO | B4: KPI | D4: SATUAN | F4: JAN | L4: FEB | R4: MAR | X4: APRIL | AD4: MEI
F5: BOBOT | G5: TARGET | H5: REAL | I5: PENCAPAIAN | J5: NILAI | L5: BOBOT | M5: TARGET | N5: REAL | O5: PENCAPAIAN | P5: NILAI | R5: BOBOT | S5: TARGET | T5: REAL | U5: PENCAPAIAN | V5: NILAI | X5: BOBOT | Y5: TARGET | Z5: REAL | AA5: PENCAPAIAN | AB5: NILAI | AD5: BOBOT | AE5: TARGET | AF5: REAL | AG5: PENCAPAIAN | AH5: NILAI
A6: 1 | B6: 2 | D6: 3 | F6: 4 | G6: 6 | H6: 7 | I6: 8 | J6: 9 | L6: 4 | M6: 6 | N6: 7 | O6: 8 | P6: 9 | R6: 4 | S6: 6 | T6: 7 | U6: 8 | V6: 9 | X6: 4 | Y6: 6 | Z6: 7 | AA6: 8 | AB6: 9 | AD6: 4 | AE6: 6 | AF6: 7 | AG6: 8 | AH6: 9
A7: =T.UP3!A7 -> I | B7: =T.UP3!B7 -> Key Performance Indikator | F7: =SUM(F8:F10) -> 28 | J7: =SUM(J8:J10) -> 15.4 | L7: =SUM(L8:L10) -> 28 | P7: =SUM(P8:P10) -> 15.4 | R7: =SUM(R8:R10) -> 28 | V7: =SUM(V8:V10) -> 15.126234 | X7: =SUM(X8:X10) -> #N/A | AB7: =SUM(AB8:AB10) -> #N/A | AD7: =SUM(AD8:AD10) -> #N/A | AH7: =SUM(AH8:AH10) -> #N/A
A8: =T.UP3!A8 -> 1 | B8: =T.UP3!B8 -> Penjualan Tenaga Listrik | C8: =T.UP3!C8 -> ñ | D8: =T.UP3!D8 -> GWh | F8: =IF(H8="N/A",0,T.UP3!$F$8) -> 14 | G8: =VLOOKUP($B$8,T.UP3!$B$4:$T$69,MATCH(DETAIL!$F$4,T.UP3!$B$5:$T$5,0),FALSE) -> 18.74 | H8: =VLOOKUP($B$8,'R.UP3'!$B$4:$S$54,MATCH(DETAIL!$F$4,'R.UP3'!$B$5:$S$5,0),FALSE) -> 22.980831 | I8: =IF(OR(G8="N/A",H8="N/A"),"N/A",IF(AND(G8=0,H8=0),0,H8/G8*100)) -> 122.62983 | J8: =IF(OR(I8="N/A",I8<0),0,IF(I8>110,F8*110/100,F8*I8/100)) -> 15.4 | L8: =IF(N8="N/A",0,T.UP3!$F$8) -> 14 | M8: =VLOOKUP($B$8,T.UP3!$B$4:$T$69,MATCH(DETAIL!$L$4,T.UP3!$B$5:$T$5,0),FALSE) -> 36.55 | N8: =VLOOKUP($B$8,'R.UP3'!$B$4:$S$54,MATCH(DETAIL!$L$4,'R.UP3'!$B$5:$S$5,0),FALSE) -> 42.202826 | O8: =IF(OR(M8="N/A",N8="N/A"),"N/A",IF(AND(M8=0,N8=0),0,N8/M8*100)) -> 115.46601 | P8: =IF(OR(O8="N/A",O8<0),0,IF(O8>110,L8*110/100,L8*O8/100)) -> 15.4 | R8: =IF(T8="N/A",0,T.UP3!$F$8) -> 14 | S8: =VLOOKUP($B$8,T.UP3!$B$4:$T$69,MATCH(DETAIL!$R$4,T.UP3!$B$5:$T$5,0),FALSE) -> 56.39 | T8: =VLOOKUP($B$8,'R.UP3'!$B$4:$S$54,MATCH(DETAIL!$R$4,'R.UP3'!$B$5:$S$5,0),FALSE) -> 60.926308 | U8: =IF(OR(S8="N/A",T8="N/A"),"N/A",IF(AND(S8=0,T8=0),0,T8/S8*100)) -> 108.04453 | V8: =IF(OR(U8="N/A",U8<0),0,IF(U8>110,R8*110/100,R8*U8/100)) -> 15.126234 | X8: =IF(Z8="N/A",0,T.UP3!$F$8) -> #N/A | Y8: =VLOOKUP($B$8,T.UP3!$B$4:$T$69,MATCH(DETAIL!$X$4,T.UP3!$B$5:$T$5,0),FALSE) -> #N/A | Z8: =VLOOKUP($B$8,'R.UP3'!$B$4:$S$54,MATCH(DETAIL!$X$4,'R.UP3'!$B$5:$S$5,0),FALSE) -> #N/A | AA8: =IF(OR(Y8="N/A",Z8="N/A"),"N/A",IF(AND(Y8=0,Z8=0),0,Z8/Y8*100)) -> #N/A | AB8: =IF(OR(AA8="N/A",AA8<0),0,IF(AA8>110,X8*110/100,X8*AA8/100)) -> #N/A | AD8: =IF(AF8="N/A",0,T.UP3!$F$8) -> #N/A | AE8: =VLOOKUP($B$8,T.UP3!$B$4:$T$69,MATCH(DETAIL!$AD$4,T.UP3!$B$5:$T$5,0),FALSE) -> #N/A | AF8: =VLOOKUP($B$8,'R.UP3'!$B$4:$S$54,MATCH(DETAIL!$AD$4,'R.UP3'!$B$5:$S$5,0),FALSE) -> #N/A | AG8: =IF(OR(AE8="N/A",AF8="N/A"),"N/A",IF(AND(AE8=0,AF8=0),0,AF8/AE8*100)) -> #N/A | AH8: =IF(OR(AG8="N/A",AG8<0),0,IF(AG8>110,AD8*110/100,AD8*AG8/100)) -> #N/A
A9: =T.UP3!A9 -> 2 | B9: =T.UP3!B9 -> Keandalan Sistem | C9: =T.UP3!C9 -> 0 | D9: =T.UP3!D9 -> 0 | F9: =IF(H9="N/A",0,T.UP3!$F$9) -> 14 | G9: =VLOOKUP($B$9,T.UP3!$B$4:$T$69,MATCH(DETAIL!$F$4,T.UP3!$B$5:$T$5,0),FALSE) -> 0 | H9: =VLOOKUP($B$9,'R.UP3'!$B$4:$S$54,MATCH(DETAIL!$F$4,'R.UP3'!$B$5:$S$5,0),FALSE) -> 0 | I9: =IF(OR(G9="N/A",H9="N/A"),"N/A",IF(AND(G9=0,H9=0),0,(2-H9/G9)*100)) -> 0 | J9: =IF(OR(I9="N/A",I9<0),0,IF(I9>110,F9*110/100,F9*I9/100)) -> 0 | L9: =IF(N9="N/A",0,T.UP3!$F$9) -> 14 | M9: =VLOOKUP($B$9,T.UP3!$B$4:$T$69,MATCH(DETAIL!$L$4,T.UP3!$B$5:$T$5,0),FALSE) -> 0 | N9: =VLOOKUP($B$9,'R.UP3'!$B$4:$S$54,MATCH(DETAIL!$L$4,'R.UP3'!$B$5:$S$5,0),FALSE) -> 0 | O9: =IF(OR(M9="N/A",N9="N/A"),"N/A",IF(AND(M9=0,N9=0),0,(2-N9/M9)*100)) -> 0 | P9: =IF(OR(O9="N/A",O9<0),0,IF(O9>110,L9*110/100,L9*O9/100)) -> 0 | R9: =IF(T9="N/A",0,T.UP3!$F$9) -> 14 | S9: =VLOOKUP($B$9,T.UP3!$B$4:$T$69,MATCH(DETAIL!$R$4,T.UP3!$B$5:$T$5,0),FALSE) -> 0 | T9: =VLOOKUP($B$9,'R.UP3'!$B$4:$S$54,MATCH(DETAIL!$R$4,'R.UP3'!$B$5:$S$5,0),FALSE) -> 0 | U9: =IF(OR(S9="N/A",T9="N/A"),"N/A",IF(AND(S9=0,T9=0),0,(2-T9/S9)*100)) -> 0 | V9: =IF(OR(U9="N/A",U9<0),0,IF(U9>110,R9*110/100,R9*U9/100)) -> 0 | X9: =IF(Z9="N/A",0,T.UP3!$F$9) -> #N/A | Y9: =VLOOKUP($B$9,T.UP3!$B$4:$T$69,MATCH(DETAIL!$X$4,T.UP3!$B$5:$T$5,0),FALSE) -> #N/A | Z9: =VLOOKUP($B$9,'R.UP3'!$B$4:$S$54,MATCH(DETAIL!$X$4,'R.UP3'!$B$5:$S$5,0),FALSE) -> #N/A | AA9: =IF(OR(Y9="N/A",Z9="N/A"),"N/A",IF(AND(Y9=0,Z9=0),0,(2-Z9/Y9)*100)) -> #N/A | AB9: =IF(OR(AA9="N/A",AA9<0),0,IF(AA9>110,X9*110/100,X9*AA9/100)) -> #N/A | AD9: =IF(AF9="N/A",0,T.UP3!$F$9) -> #N/A | AE9: =VLOOKUP($B$9,T.UP3!$B$4:$T$69,MATCH(DETAIL!$AD$4,T.UP3!$B$5:$T$5,0),FALSE) -> #N/A | AF9: =VLOOKUP($B$9,'R.UP3'!$B$4:$S$54,MATCH(DETAIL!$AD$4,'R.UP3'!$B$5:$S$5,0),FALSE) -> #N/A | AG9: =IF(OR(AE9="N/A",AF9="N/A"),"N/A",IF(AND(AE9=0,AF9=0),0,(2-AF9/AE9)*100)) -> #N/A | AH9: =IF(OR(AG9="N/A",AG9<0),0,IF(AG9>110,AD9*110/100,AD9*AG9/100)) -> #N/A
A10: =T.UP3!A10 -> 0 | B10: =T.UP3!B10 -> a. SAIDI Sesuai Kewenangannya | C10: =T.UP3!C10 -> ò | D10: =T.UP3!D10 -> Menit/Plg | F10: =IF(H10="N/A",0,T.UP3!$F$10) -> 0 | G10: =VLOOKUP($B$10,T.UP3!$B$4:$T$69,MATCH(DETAIL!$F$4,T.UP3!$B$5:$T$5,0),FALSE) -> 23.39 | H10: =VLOOKUP($B$10,'R.UP3'!$B$4:$S$54,MATCH(DETAIL!$F$4,'R.UP3'!$B$5:$S$5,0),FALSE) -> 12.366709 | I10: =IF(OR(G10="N/A",H10="N/A"),"N/A",IF(AND(G10=0,H10=0),0,H10/G10*100)) -> 52.871777 | J10: =IF(OR(I10="N/A",I10<0),0,IF(I10>110,F10*110/100,F10*I10/100)) -> 0 | L10: =IF(N10="N/A",0,T.UP3!$F$10) -> 0 | M10: =VLOOKUP($B$10,T.UP3!$B$4:$T$69,MATCH(DETAIL!$L$4,T.UP3!$B$5:$T$5,0),FALSE) -> 46.78 | N10: =VLOOKUP($B$10,'R.UP3'!$B$4:$S$54,MATCH(DETAIL!$L$4,'R.UP3'!$B$5:$S$5,0),FALSE) -> 14.217818 | O10: =IF(OR(M10="N/A",N10="N/A"),"N/A",IF(AND(M10=0,N10=0),0,N10/M10*100)) -> 30.392942 | P10: =IF(OR(O10="N/A",O10<0),0,IF(O10>110,L10*110/100,L10*O10/100)) -> 0 | R10: =IF(T10="N/A",0,T.UP3!$F$10) -> 0 | S10: =VLOOKUP($B$10,T.UP3!$B$4:$T$69,MATCH(DETAIL!$R$4,T.UP3!$B$5:$T$5,0),FALSE) -> 70.17 | T10: =VLOOKUP($B$10,'R.UP3'!$B$4:$S$54,MATCH(DETAIL!$R$4,'R.UP3'!$B$5:$S$5,0),FALSE) -> 15.90799 | U10: =IF(OR(S10="N/A",T10="N/A"),"N/A",IF(AND(S10=0,T10=0),0,T10/S10*100)) -> 22.670642 | V10: =IF(OR(U10="N/A",U10<0),0,IF(U10>110,R10*110/100,R10*U10/100)) -> 0 | X10: =IF(Z10="N/A",0,T.UP3!$F$10) -> #N/A | Y10: =VLOOKUP($B$10,T.UP3!$B$4:$T$69,MATCH(DETAIL!$X$4,T.UP3!$B$5:$T$5,0),FALSE) -> #N/A | Z10: =VLOOKUP($B$10,'R.UP3'!$B$4:$S$54,MATCH(DETAIL!$X$4,'R.UP3'!$B$5:$S$5,0),FALSE) -> #N/A | AA10: =IF(OR(Y10="N/A",Z10="N/A"),"N/A",IF(AND(Y10=0,Z10=0),0,Z10/Y10*100)) -> #N/A | AB10: =IF(OR(AA10="N/A",AA10<0),0,IF(AA10>110,X10*110/100,X10*AA10/100)) -> #N/A | AD10: =IF(AF10="N/A",0,T.UP3!$F$10) -> #N/A | AE10: =VLOOKUP($B$10,T.UP3!$B$4:$T$69,MATCH(DETAIL!$AD$4,T.UP3!$B$5:$T$5,0),FALSE) -> #N/A | AF10: =VLOOKUP($B$10,'R.UP3'!$B$4:$S$54,MATCH(DETAIL!$AD$4,'R.UP3'!$B$5:$S$5,0),FALSE) -> #N/A | AG10: =IF(OR(AE10="N/A",AF10="N/A"),"N/A",IF(AND(AE10=0,AF10=0),0,AF10/AE10*100)) -> #N/A | AH10: =IF(OR(AG10="N/A",AG10<0),0,IF(AG10>110,AD10*110/100,AD10*AG10/100)) -> #N/A
A11: =T.UP3!A17 -> II | B11: =T.UP3!B17 -> Perfomance Indicators | F11: =SUM(F12:F41) -> #REF! | J11: =SUM(J12:J41) -> #REF! | L11: =SUM(L12:L41) -> #REF! | P11: =SUM(P12:P41) -> #REF! | R11: =SUM(R12:R41) -> #REF! | V11: =SUM(V12:V41) -> #REF! | X11: =SUM(X12:X41) -> #N/A | AB11: =SUM(AB12:AB41) -> #N/A | AD11: =SUM(AD12:AD41) -> #N/A | AH11: =SUM(AH12:AH41) -> #N/A
A12: =T.UP3!A18 -> 4 | B12: =T.UP3!B18 -> Keandalan Jaringan Distribusi | C12: =T.UP3!C18 -> 0 | D12: =T.UP3!D18 -> 0 | F12: =IF(H12="N/A",0,T.UP3!$F$18) -> 6 | G12: =VLOOKUP($B$12,T.UP3!$B$4:$T$69,MATCH(DETAIL!$F$4,T.UP3!$B$5:$T$5,0),FALSE) -> 0 | H12: =VLOOKUP($B$12,'R.UP3'!$B$4:$S$54,MATCH(DETAIL!$F$4,'R.UP3'!$B$5:$S$5,0),FALSE) -> 0 | I12: =IF(OR(G12="N/A",H12="N/A"),"N/A",IF(AND(G12=0,H12=0),0,(2-H12/G12)*100)) -> 0 | J12: =IF(I12="N/A",0,IF(I12>110,F12*110/100,F12*I12/100)) -> 0 | L12: =IF(N12="N/A",0,T.UP3!$F$18) -> 6 | M12: =VLOOKUP($B$12,T.UP3!$B$4:$T$69,MATCH(DETAIL!$L$4,T.UP3!$B$5:$T$5,0),FALSE) -> 0 | N12: =VLOOKUP($B$12,'R.UP3'!$B$4:$S$54,MATCH(DETAIL!$L$4,'R.UP3'!$B$5:$S$5,0),FALSE) -> 0 | O12: =IF(OR(M12="N/A",N12="N/A"),"N/A",IF(AND(M12=0,N12=0),0,(2-N12/M12)*100)) -> 0 | P12: =IF(O12="N/A",0,IF(O12>110,L12*110/100,L12*O12/100)) -> 0 | R12: =IF(T12="N/A",0,T.UP3!$F$18) -> 6 | S12: =VLOOKUP($B$12,T.UP3!$B$4:$T$69,MATCH(DETAIL!$R$4,T.UP3!$B$5:$T$5,0),FALSE) -> 0 | T12: =VLOOKUP($B$12,'R.UP3'!$B$4:$S$54,MATCH(DETAIL!$R$4,'R.UP3'!$B$5:$S$5,0),FALSE) -> 0 | U12: =IF(OR(S12="N/A",T12="N/A"),"N/A",IF(AND(S12=0,T12=0),0,(2-T12/S12)*100)) -> 0 | V12: =IF(U12="N/A",0,IF(U12>110,R12*110/100,R12*U12/100)) -> 0 | X12: =IF(Z12="N/A",0,T.UP3!$F$18) -> #N/A | Y12: =VLOOKUP($B$12,T.UP3!$B$4:$T$69,MATCH(DETAIL!$X$4,T.UP3!$B$5:$T$5,0),FALSE) -> #N/A | Z12: =VLOOKUP($B$12,'R.UP3'!$B$4:$S$54,MATCH(DETAIL!$X$4,'R.UP3'!$B$5:$S$5,0),FALSE) -> #N/A | AA12: =IF(OR(Y12="N/A",Z12="N/A"),"N/A",IF(AND(Y12=0,Z12=0),0,(2-Z12/Y12)*100)) -> #N/A | AB12: =IF(AA12="N/A",0,IF(AA12>110,X12*110/100,X12*AA12/100)) -> #N/A | AD12: =IF(AF12="N/A",0,T.UP3!$F$18) -> #N/A | AE12: =VLOOKUP($B$12,T.UP3!$B$4:$T$69,MATCH(DETAIL!$AD$4,T.UP3!$B$5:$T$5,0),FALSE) -> #N/A | AF12: =VLOOKUP($B$12,'R.UP3'!$B$4:$S$54,MATCH(DETAIL!$AD$4,'R.UP3'!$B$5:$S$5,0),FALSE) -> #N/A | AG12: =IF(OR(AE12="N/A",AF12="N/A"),"N/A",IF(AND(AE12=0,AF12=0),0,(2-AF12/AE12)*100)) -> #N/A | AH12: =IF(AG12="N/A",0,IF(AG12>110,AD12*110/100,AD12*AG12/100)) -> #N/A
A13: =T.UP3!A19 -> 0 | B13: =T.UP3!B19 -> a. Gangguan TM > 5 Menit | C13: =T.UP3!C19 -> ò | D13: =T.UP3!D19 -> Kali | F13: =IF(H13="N/A",0,T.UP3!$F$19) -> 0 | G13: =VLOOKUP($B$13,T.UP3!$B$4:$T$69,MATCH(DETAIL!$F$4,T.UP3!$B$5:$T$5,0),FALSE) -> 15 | H13: =VLOOKUP($B$13,'R.UP3'!$B$4:$S$54,MATCH(DETAIL!$F$4,'R.UP3'!$B$5:$S$5,0),FALSE) -> 5 | I13: =IF(OR(G13="N/A",H13="N/A"),"N/A",IF(AND(G13=0,H13=0),0,(2-H13/G13)*100)) -> 166.66667 | J13: =IF(I13="N/A",0,IF(I13>110,F13*110/100,F13*I13/100)) -> 0 | L13: =IF(N13="N/A",0,T.UP3!$F$19) -> 0 | M13: =VLOOKUP($B$13,T.UP3!$B$4:$T$69,MATCH(DETAIL!$L$4,T.UP3!$B$5:$T$5,0),FALSE) -> 29 | N13: =VLOOKUP($B$13,'R.UP3'!$B$4:$S$54,MATCH(DETAIL!$L$4,'R.UP3'!$B$5:$S$5,0),FALSE) -> 10 | O13: =IF(OR(M13="N/A",N13="N/A"),"N/A",IF(AND(M13=0,N13=0),0,(2-N13/M13)*100)) -> 165.51724 | P13: =IF(O13="N/A",0,IF(O13>110,L13*110/100,L13*O13/100)) -> 0 | R13: =IF(T13="N/A",0,T.UP3!$F$19) -> 0 | S13: =VLOOKUP($B$13,T.UP3!$B$4:$T$69,MATCH(DETAIL!$R$4,T.UP3!$B$5:$T$5,0),FALSE) -> 45 | T13: =VLOOKUP($B$13,'R.UP3'!$B$4:$S$54,MATCH(DETAIL!$R$4,'R.UP3'!$B$5:$S$5,0),FALSE) -> 32 | U13: =IF(OR(S13="N/A",T13="N/A"),"N/A",IF(AND(S13=0,T13=0),0,(2-T13/S13)*100)) -> 128.88889 | V13: =IF(U13="N/A",0,IF(U13>110,R13*110/100,R13*U13/100)) -> 0 | X13: =IF(Z13="N/A",0,T.UP3!$F$19) -> #N/A | Y13: =VLOOKUP($B$13,T.UP3!$B$4:$T$69,MATCH(DETAIL!$X$4,T.UP3!$B$5:$T$5,0),FALSE) -> #N/A | Z13: =VLOOKUP($B$13,'R.UP3'!$B$4:$S$54,MATCH(DETAIL!$X$4,'R.UP3'!$B$5:$S$5,0),FALSE) -> #N/A | AA13: =IF(OR(Y13="N/A",Z13="N/A"),"N/A",IF(AND(Y13=0,Z13=0),0,(2-Z13/Y13)*100)) -> #N/A | AB13: =IF(AA13="N/A",0,IF(AA13>110,X13*110/100,X13*AA13/100)) -> #N/A | AD13: =IF(AF13="N/A",0,T.UP3!$F$19) -> #N/A | AE13: =VLOOKUP($B$13,T.UP3!$B$4:$T$69,MATCH(DETAIL!$AD$4,T.UP3!$B$5:$T$5,0),FALSE) -> #N/A | AF13: =VLOOKUP($B$13,'R.UP3'!$B$4:$S$54,MATCH(DETAIL!$AD$4,'R.UP3'!$B$5:$S$5,0),FALSE) -> #N/A | AG13: =IF(OR(AE13="N/A",AF13="N/A"),"N/A",IF(AND(AE13=0,AF13=0),0,(2-AF13/AE13)*100)) -> #N/A | AH13: =IF(AG13="N/A",0,IF(AG13>110,AD13*110/100,AD13*AG13/100)) -> #N/A
A14: =T.UP3!A20 -> 0 | B14: =T.UP3!B20 -> b. Gangguan TM ≤ 5 Menit | C14: =T.UP3!C20 -> ò | D14: =T.UP3!D20 -> Kali | F14: =IF(H14="N/A",0,T.UP3!$F$20) -> 0 | G14: =VLOOKUP($B$14,T.UP3!$B$4:$T$69,MATCH(DETAIL!$F$4,T.UP3!$B$5:$T$5,0),FALSE) -> 17 | H14: =VLOOKUP($B$14,'R.UP3'!$B$4:$S$54,MATCH(DETAIL!$F$4,'R.UP3'!$B$5:$S$5,0),FALSE) -> 1 | I14: =IF(OR(G14="N/A",H14="N/A"),"N/A",IF(AND(G14=0,H14=0),0,(2-H14/G14)*100)) -> 194.11765 | J14: =IF(I14="N/A",0,IF(I14>110,F14*110/100,F14*I14/100)) -> 0 | L14: =IF(N14="N/A",0,T.UP3!$F$20) -> 0 | M14: =VLOOKUP($B$14,T.UP3!$B$4:$T$69,MATCH(DETAIL!$L$4,T.UP3!$B$5:$T$5,0),FALSE) -> 31 | N14: =VLOOKUP($B$14,'R.UP3'!$B$4:$S$54,MATCH(DETAIL!$L$4,'R.UP3'!$B$5:$S$5,0),FALSE) -> 18 | O14: =IF(OR(M14="N/A",N14="N/A"),"N/A",IF(AND(M14=0,N14=0),0,(2-N14/M14)*100)) -> 141.93548 | P14: =IF(O14="N/A",0,IF(O14>110,L14*110/100,L14*O14/100)) -> 0 | R14: =IF(T14="N/A",0,T.UP3!$F$20) -> 0 | S14: =VLOOKUP($B$14,T.UP3!$B$4:$T$69,MATCH(DETAIL!$R$4,T.UP3!$B$5:$T$5,0),FALSE) -> 48 | T14: =VLOOKUP($B$14,'R.UP3'!$B$4:$S$54,MATCH(DETAIL!$R$4,'R.UP3'!$B$5:$S$5,0),FALSE) -> 21 | U14: =IF(OR(S14="N/A",T14="N/A"),"N/A",IF(AND(S14=0,T14=0),0,(2-T14/S14)*100)) -> 156.25 | V14: =IF(U14="N/A",0,IF(U14>110,R14*110/100,R14*U14/100)) -> 0 | X14: =IF(Z14="N/A",0,T.UP3!$F$20) -> #N/A | Y14: =VLOOKUP($B$14,T.UP3!$B$4:$T$69,MATCH(DETAIL!$X$4,T.UP3!$B$5:$T$5,0),FALSE) -> #N/A | Z14: =VLOOKUP($B$14,'R.UP3'!$B$4:$S$54,MATCH(DETAIL!$X$4,'R.UP3'!$B$5:$S$5,0),FALSE) -> #N/A | AA14: =IF(OR(Y14="N/A",Z14="N/A"),"N/A",IF(AND(Y14=0,Z14=0),0,(2-Z14/Y14)*100)) -> #N/A | AB14: =IF(AA14="N/A",0,IF(AA14>110,X14*110/100,X14*AA14/100)) -> #N/A | AD14: =IF(AF14="N/A",0,T.UP3!$F$20) -> #N/A | AE14: =VLOOKUP($B$14,T.UP3!$B$4:$T$69,MATCH(DETAIL!$AD$4,T.UP3!$B$5:$T$5,0),FALSE) -> #N/A | AF14: =VLOOKUP($B$14,'R.UP3'!$B$4:$S$54,MATCH(DETAIL!$AD$4,'R.UP3'!$B$5:$S$5,0),FALSE) -> #N/A | AG14: =IF(OR(AE14="N/A",AF14="N/A"),"N/A",IF(AND(AE14=0,AF14=0),0,(2-AF14/AE14)*100)) -> #N/A | AH14: =IF(AG14="N/A",0,IF(AG14>110,AD14*110/100,AD14*AG14/100)) -> #N/A
A15: =T.UP3!A21 -> 0 | B15: =T.UP3!B21 -> c. Kerusakan Peralatan Distribusi (PHB TM dan Trafo) Sesuai Kewenangan
B16: =T.UP3!B22 -> Peningkatan Layanan | C16: =T.UP3!C22 -> 0 | D16: =T.UP3!D22 -> 0 | F16: =IF(H16="N/A",0,T.UP3!$F$22) -> 6 | G16: =VLOOKUP($B$16,T.UP3!$B$4:$T$69,MATCH(DETAIL!$F$4,T.UP3!$B$5:$T$5,0),FALSE) -> 0 | H16: =VLOOKUP($B$16,'R.UP3'!$B$4:$S$54,MATCH(DETAIL!$F$4,'R.UP3'!$B$5:$S$5,0),FALSE) -> 0 | I16: =IF(OR(G16="N/A",H16="N/A"),"N/A",IF(AND(G16=0,H16=0),0,(2-H16/G16)*100)) -> 0 | J16: =IF(I16="N/A",0,IF(I16>110,F16*110/100,F16*I16/100)) -> 0 | L16: =IF(N16="N/A",0,T.UP3!$F$22) -> 6 | M16: =VLOOKUP($B$16,T.UP3!$B$4:$T$69,MATCH(DETAIL!$L$4,T.UP3!$B$5:$T$5,0),FALSE) -> 0 | N16: =VLOOKUP($B$16,'R.UP3'!$B$4:$S$54,MATCH(DETAIL!$L$4,'R.UP3'!$B$5:$S$5,0),FALSE) -> 0 | O16: =IF(OR(M16="N/A",N16="N/A"),"N/A",IF(AND(M16=0,N16=0),0,(2-N16/M16)*100)) -> 0 | P16: =IF(O16="N/A",0,IF(O16>110,L16*110/100,L16*O16/100)) -> 0 | R16: =IF(T16="N/A",0,T.UP3!$F$22) -> 6 | S16: =VLOOKUP($B$16,T.UP3!$B$4:$T$69,MATCH(DETAIL!$R$4,T.UP3!$B$5:$T$5,0),FALSE) -> 0 | T16: =VLOOKUP($B$16,'R.UP3'!$B$4:$S$54,MATCH(DETAIL!$R$4,'R.UP3'!$B$5:$S$5,0),FALSE) -> 0 | U16: =IF(OR(S16="N/A",T16="N/A"),"N/A",IF(AND(S16=0,T16=0),0,(2-T16/S16)*100)) -> 0 | V16: =IF(U16="N/A",0,IF(U16>110,R16*110/100,R16*U16/100)) -> 0 | X16: =IF(Z16="N/A",0,T.UP3!$F$22) -> #N/A | Y16: =VLOOKUP($B$16,T.UP3!$B$4:$T$69,MATCH(DETAIL!$X$4,T.UP3!$B$5:$T$5,0),FALSE) -> #N/A | Z16: =VLOOKUP($B$16,'R.UP3'!$B$4:$S$54,MATCH(DETAIL!$X$4,'R.UP3'!$B$5:$S$5,0),FALSE) -> #N/A | AA16: =IF(OR(Y16="N/A",Z16="N/A"),"N/A",IF(AND(Y16=0,Z16=0),0,(2-Z16/Y16)*100)) -> #N/A | AB16: =IF(AA16="N/A",0,IF(AA16>110,X16*110/100,X16*AA16/100)) -> #N/A | AD16: =IF(AF16="N/A",0,T.UP3!$F$22) -> #N/A | AE16: =VLOOKUP($B$16,T.UP3!$B$4:$T$69,MATCH(DETAIL!$AD$4,T.UP3!$B$5:$T$5,0),FALSE) -> #N/A | AF16: =VLOOKUP($B$16,'R.UP3'!$B$4:$S$54,MATCH(DETAIL!$AD$4,'R.UP3'!$B$5:$S$5,0),FALSE) -> #N/A | AG16: =IF(OR(AE16="N/A",AF16="N/A"),"N/A",IF(AND(AE16=0,AF16=0),0,(2-AF16/AE16)*100)) -> #N/A | AH16: =IF(AG16="N/A",0,IF(AG16>110,AD16*110/100,AD16*AG16/100)) -> #N/A
B17: =T.UP3!B24 -> b. Pengaduan Gangguan Berulang pada PLN Mobile | C17: =T.UP3!C24 -> ò | D17: =T.UP3!D24 -> % | F17: =IF(H17="N/A",0,T.UP3!$F$24) -> 0 | G17: =VLOOKUP($B$17,T.UP3!$B$4:$T$69,MATCH(DETAIL!$F$4,T.UP3!$B$5:$T$5,0),FALSE) -> 0.04 | H17: =VLOOKUP($B$17,'R.UP3'!$B$4:$S$54,MATCH(DETAIL!$F$4,'R.UP3'!$B$5:$S$5,0),FALSE) -> 0 | I17: =IF(OR(G17="N/A",H17="N/A"),"N/A",IF(AND(G17=0,H17=0),0,(2-H17/G17)*100)) -> 200 | J17: =IF(I17="N/A",0,IF(I17>110,F17*110/100,F17*I17/100)) -> 0 | L17: =IF(N17="N/A",0,T.UP3!$F$24) -> 0 | M17: =VLOOKUP($B$17,T.UP3!$B$4:$T$69,MATCH(DETAIL!$L$4,T.UP3!$B$5:$T$5,0),FALSE) -> 0.04 | N17: =VLOOKUP($B$17,'R.UP3'!$B$4:$S$54,MATCH(DETAIL!$L$4,'R.UP3'!$B$5:$S$5,0),FALSE) -> 0 | O17: =IF(OR(M17="N/A",N17="N/A"),"N/A",IF(AND(M17=0,N17=0),0,(2-N17/M17)*100)) -> 200 | P17: =IF(O17="N/A",0,IF(O17>110,L17*110/100,L17*O17/100)) -> 0 | R17: =IF(T17="N/A",0,T.UP3!$F$24) -> 0 | S17: =VLOOKUP($B$17,T.UP3!$B$4:$T$69,MATCH(DETAIL!$R$4,T.UP3!$B$5:$T$5,0),FALSE) -> 0.04 | T17: =VLOOKUP($B$17,'R.UP3'!$B$4:$S$54,MATCH(DETAIL!$R$4,'R.UP3'!$B$5:$S$5,0),FALSE) -> 0 | U17: =IF(OR(S17="N/A",T17="N/A"),"N/A",IF(AND(S17=0,T17=0),0,(2-T17/S17)*100)) -> 200 | V17: =IF(U17="N/A",0,IF(U17>110,R17*110/100,R17*U17/100)) -> 0 | X17: =IF(Z17="N/A",0,T.UP3!$F$24) -> #N/A | Y17: =VLOOKUP($B$17,T.UP3!$B$4:$T$69,MATCH(DETAIL!$X$4,T.UP3!$B$5:$T$5,0),FALSE) -> #N/A | Z17: =VLOOKUP($B$17,'R.UP3'!$B$4:$S$54,MATCH(DETAIL!$X$4,'R.UP3'!$B$5:$S$5,0),FALSE) -> #N/A | AA17: =IF(OR(Y17="N/A",Z17="N/A"),"N/A",IF(AND(Y17=0,Z17=0),0,(2-Z17/Y17)*100)) -> #N/A | AB17: =IF(AA17="N/A",0,IF(AA17>110,X17*110/100,X17*AA17/100)) -> #N/A | AD17: =IF(AF17="N/A",0,T.UP3!$F$24) -> #N/A | AE17: =VLOOKUP($B$17,T.UP3!$B$4:$T$69,MATCH(DETAIL!$AD$4,T.UP3!$B$5:$T$5,0),FALSE) -> #N/A | AF17: =VLOOKUP($B$17,'R.UP3'!$B$4:$S$54,MATCH(DETAIL!$AD$4,'R.UP3'!$B$5:$S$5,0),FALSE) -> #N/A | AG17: =IF(OR(AE17="N/A",AF17="N/A"),"N/A",IF(AND(AE17=0,AF17=0),0,(2-AF17/AE17)*100)) -> #N/A | AH17: =IF(AG17="N/A",0,IF(AG17>110,AD17*110/100,AD17*AG17/100)) -> #N/A
A18: =T.UP3!A25 -> 0 | B18: =T.UP3!B25 -> c. Rating PLN Mobile | C18: =T.UP3!C25 -> ñ | D18: =T.UP3!D25 -> Rating | F18: =IF(H18="N/A",0,T.UP3!$F$25) -> 0 | G18: =VLOOKUP($B$18,T.UP3!$B$4:$T$69,MATCH(DETAIL!$F$4,T.UP3!$B$5:$T$5,0),FALSE) -> 4.9 | H18: =VLOOKUP($B$18,'R.UP3'!$B$4:$S$54,MATCH(DETAIL!$F$4,'R.UP3'!$B$5:$S$5,0),FALSE) -> 4.91 | I18: =IF(OR(G18="N/A",H18="N/A"),"N/A",IF(AND(G18=0,H18=0),0,H18/G18*100)) -> 100.20408 | J18: =IF(I18="N/A",0,IF(I18>110,F18*110/100,F18*I18/100)) -> 0 | L18: =IF(N18="N/A",0,T.UP3!$F$25) -> 0 | M18: =VLOOKUP($B$18,T.UP3!$B$4:$T$69,MATCH(DETAIL!$L$4,T.UP3!$B$5:$T$5,0),FALSE) -> 4.9 | N18: =VLOOKUP($B$18,'R.UP3'!$B$4:$S$54,MATCH(DETAIL!$L$4,'R.UP3'!$B$5:$S$5,0),FALSE) -> 4.91 | O18: =IF(OR(M18="N/A",N18="N/A"),"N/A",IF(AND(M18=0,N18=0),0,N18/M18*100)) -> 100.20408 | P18: =IF(O18="N/A",0,IF(O18>110,L18*110/100,L18*O18/100)) -> 0 | R18: =IF(T18="N/A",0,T.UP3!$F$25) -> 0 | S18: =VLOOKUP($B$18,T.UP3!$B$4:$T$69,MATCH(DETAIL!$R$4,T.UP3!$B$5:$T$5,0),FALSE) -> 4.9 | T18: =VLOOKUP($B$18,'R.UP3'!$B$4:$S$54,MATCH(DETAIL!$R$4,'R.UP3'!$B$5:$S$5,0),FALSE) -> 4.91 | U18: =IF(OR(S18="N/A",T18="N/A"),"N/A",IF(AND(S18=0,T18=0),0,T18/S18*100)) -> 100.20408 | V18: =IF(U18="N/A",0,IF(U18>110,R18*110/100,R18*U18/100)) -> 0 | X18: =IF(Z18="N/A",0,T.UP3!$F$25) -> #N/A | Y18: =VLOOKUP($B$18,T.UP3!$B$4:$T$69,MATCH(DETAIL!$X$4,T.UP3!$B$5:$T$5,0),FALSE) -> #N/A | Z18: =VLOOKUP($B$18,'R.UP3'!$B$4:$S$54,MATCH(DETAIL!$X$4,'R.UP3'!$B$5:$S$5,0),FALSE) -> #N/A | AA18: =IF(OR(Y18="N/A",Z18="N/A"),"N/A",IF(AND(Y18=0,Z18=0),0,Z18/Y18*100)) -> #N/A | AB18: =IF(AA18="N/A",0,IF(AA18>110,X18*110/100,X18*AA18/100)) -> #N/A | AD18: =IF(AF18="N/A",0,T.UP3!$F$25) -> #N/A | AE18: =VLOOKUP($B$18,T.UP3!$B$4:$T$69,MATCH(DETAIL!$AD$4,T.UP3!$B$5:$T$5,0),FALSE) -> #N/A | AF18: =VLOOKUP($B$18,'R.UP3'!$B$4:$S$54,MATCH(DETAIL!$AD$4,'R.UP3'!$B$5:$S$5,0),FALSE) -> #N/A | AG18: =IF(OR(AE18="N/A",AF18="N/A"),"N/A",IF(AND(AE18=0,AF18=0),0,AF18/AE18*100)) -> #N/A | AH18: =IF(AG18="N/A",0,IF(AG18>110,AD18*110/100,AD18*AG18/100)) -> #N/A
A19: =T.UP3!#REF! -> #REF! | B19: =T.UP3!#REF! -> #REF!
B20: =T.UP3!B26 -> d. Jumlah Kali Transaksi Keuangan melalui PLN Mobile | C20: =T.UP3!C26 -> ñ | D20: =T.UP3!D26 -> Kali Transaksi | F20: =IF(H20="N/A",0,T.UP3!$F$26) -> 0 | G20: =VLOOKUP($B$20,T.UP3!$B$4:$T$69,MATCH(DETAIL!$F$4,T.UP3!$B$5:$T$5,0),FALSE) -> 5386 | H20: =VLOOKUP($B$20,'R.UP3'!$B$4:$S$54,MATCH(DETAIL!$F$4,'R.UP3'!$B$5:$S$5,0),FALSE) -> 2781 | I20: =IF(OR(G20="N/A",H20="N/A"),"N/A",IF(AND(G20=0,H20=0),0,IF(H20<0,0,(2-H20/G20)*100))) -> 148.36613 | J20: =IF(OR(I20="N/A",I20<0),0,IF(I20>110,F20*110/100,F20*I20/100)) -> 0 | L20: =IF(N20="N/A",0,T.UP3!$F$26) -> 0 | M20: =VLOOKUP($B$20,T.UP3!$B$4:$T$69,MATCH(DETAIL!$L$4,T.UP3!$B$5:$T$5,0),FALSE) -> 10253 | N20: =VLOOKUP($B$20,'R.UP3'!$B$4:$S$54,MATCH(DETAIL!$L$4,'R.UP3'!$B$5:$S$5,0),FALSE) -> 6163 | O20: =IF(OR(M20="N/A",N20="N/A"),"N/A",IF(AND(M20=0,N20=0),0,IF(N20<0,0,(2-N20/M20)*100))) -> 139.89076 | P20: =IF(OR(O20="N/A",O20<0),0,IF(O20>110,L20*110/100,L20*O20/100)) -> 0 | R20: =IF(T20="N/A",0,T.UP3!$F$26) -> 0 | S20: =VLOOKUP($B$20,T.UP3!$B$4:$T$69,MATCH(DETAIL!$R$4,T.UP3!$B$5:$T$5,0),FALSE) -> 15641 | T20: =VLOOKUP($B$20,'R.UP3'!$B$4:$S$54,MATCH(DETAIL!$R$4,'R.UP3'!$B$5:$S$5,0),FALSE) -> 16349 | U20: =IF(OR(S20="N/A",T20="N/A"),"N/A",IF(AND(S20=0,T20=0),0,IF(T20<0,0,(2-T20/S20)*100))) -> 95.473435 | V20: =IF(OR(U20="N/A",U20<0),0,IF(U20>110,R20*110/100,R20*U20/100)) -> 0 | X20: =IF(Z20="N/A",0,T.UP3!$F$26) -> #N/A | Y20: =VLOOKUP($B$20,T.UP3!$B$4:$T$69,MATCH(DETAIL!$X$4,T.UP3!$B$5:$T$5,0),FALSE) -> #N/A | Z20: =VLOOKUP($B$20,'R.UP3'!$B$4:$S$54,MATCH(DETAIL!$X$4,'R.UP3'!$B$5:$S$5,0),FALSE) -> #N/A | AA20: =IF(OR(Y20="N/A",Z20="N/A"),"N/A",IF(AND(Y20=0,Z20=0),0,IF(Z20<0,0,(2-Z20/Y20)*100))) -> #N/A | AB20: =IF(OR(AA20="N/A",AA20<0),0,IF(AA20>110,X20*110/100,X20*AA20/100)) -> #N/A | AD20: =IF(AF20="N/A",0,T.UP3!$F$26) -> #N/A | AE20: =VLOOKUP($B$20,T.UP3!$B$4:$T$69,MATCH(DETAIL!$AD$4,T.UP3!$B$5:$T$5,0),FALSE) -> #N/A | AF20: =VLOOKUP($B$20,'R.UP3'!$B$4:$S$54,MATCH(DETAIL!$AD$4,'R.UP3'!$B$5:$S$5,0),FALSE) -> #N/A | AG20: =IF(OR(AE20="N/A",AF20="N/A"),"N/A",IF(AND(AE20=0,AF20=0),0,IF(AF20<0,0,(2-AF20/AE20)*100))) -> #N/A | AH20: =IF(OR(AG20="N/A",AG20<0),0,IF(AG20>110,AD20*110/100,AD20*AG20/100)) -> #N/A
B21: =T.UP3!#REF! -> #REF! | C21: =T.UP3!#REF! -> #REF! | D21: =T.UP3!#REF! -> #REF! | F21: =IF(H21="N/A",0,T.UP3!#REF!) -> #REF! | G21: =VLOOKUP($B$21,T.UP3!$B$4:$T$69,MATCH(DETAIL!$F$4,T.UP3!$B$5:$T$5,0),FALSE) -> #REF! | H21: =VLOOKUP($B$21,'R.UP3'!$B$4:$S$54,MATCH(DETAIL!$F$4,'R.UP3'!$B$5:$S$5,0),FALSE) -> #REF! | I21: =IF(OR(G21="N/A",H21="N/A"),"N/A",IF(AND(G21=0,H21=0),0,(2-H21/G21)*100)) -> #REF! | J21: =IF(OR(I21="N/A",I21<0),0,IF(I21>110,F21*110/100,F21*I21/100)) -> #REF! | L21: =IF(N21="N/A",0,T.UP3!#REF!) -> #REF! | M21: =VLOOKUP($B$21,T.UP3!$B$4:$T$69,MATCH(DETAIL!$L$4,T.UP3!$B$5:$T$5,0),FALSE) -> #REF! | N21: =VLOOKUP($B$21,'R.UP3'!$B$4:$S$54,MATCH(DETAIL!$L$4,'R.UP3'!$B$5:$S$5,0),FALSE) -> #REF! | O21: =IF(OR(M21="N/A",N21="N/A"),"N/A",IF(AND(M21=0,N21=0),0,(2-N21/M21)*100)) -> #REF! | P21: =IF(OR(O21="N/A",O21<0),0,IF(O21>110,L21*110/100,L21*O21/100)) -> #REF! | R21: =IF(T21="N/A",0,T.UP3!#REF!) -> #REF! | S21: =VLOOKUP($B$21,T.UP3!$B$4:$T$69,MATCH(DETAIL!$R$4,T.UP3!$B$5:$T$5,0),FALSE) -> #REF! | T21: =VLOOKUP($B$21,'R.UP3'!$B$4:$S$54,MATCH(DETAIL!$R$4,'R.UP3'!$B$5:$S$5,0),FALSE) -> #REF! | U21: =IF(OR(S21="N/A",T21="N/A"),"N/A",IF(AND(S21=0,T21=0),0,(2-T21/S21)*100)) -> #REF! | V21: =IF(OR(U21="N/A",U21<0),0,IF(U21>110,R21*110/100,R21*U21/100)) -> #REF! | X21: =IF(Z21="N/A",0,T.UP3!#REF!) -> #REF! | Y21: =VLOOKUP($B$21,T.UP3!$B$4:$T$69,MATCH(DETAIL!$X$4,T.UP3!$B$5:$T$5,0),FALSE) -> #REF! | Z21: =VLOOKUP($B$21,'R.UP3'!$B$4:$S$54,MATCH(DETAIL!$X$4,'R.UP3'!$B$5:$S$5,0),FALSE) -> #REF! | AA21: =IF(OR(Y21="N/A",Z21="N/A"),"N/A",IF(AND(Y21=0,Z21=0),0,(2-Z21/Y21)*100)) -> #REF! | AB21: =IF(OR(AA21="N/A",AA21<0),0,IF(AA21>110,X21*110/100,X21*AA21/100)) -> #REF! | AD21: =IF(AF21="N/A",0,T.UP3!#REF!) -> #REF! | AE21: =VLOOKUP($B$21,T.UP3!$B$4:$T$69,MATCH(DETAIL!$AD$4,T.UP3!$B$5:$T$5,0),FALSE) -> #REF! | AF21: =VLOOKUP($B$21,'R.UP3'!$B$4:$S$54,MATCH(DETAIL!$AD$4,'R.UP3'!$B$5:$S$5,0),FALSE) -> #REF! | AG21: =IF(OR(AE21="N/A",AF21="N/A"),"N/A",IF(AND(AE21=0,AF21=0),0,(2-AF21/AE21)*100)) -> #REF! | AH21: =IF(OR(AG21="N/A",AG21<0),0,IF(AG21>110,AD21*110/100,AD21*AG21/100)) -> #REF!
A22: =T.UP3!A37 -> 0 | B22: =T.UP3!B37 -> b. Penambahan Jumlah Pelanggan | C22: =T.UP3!C37 -> ñ | D22: =T.UP3!D37 -> Pelanggan | F22: =IF(H22="N/A",0,T.UP3!$F$37) -> 2 | G22: =VLOOKUP($B$22,T.UP3!$B$4:$T$69,MATCH(DETAIL!$F$4,T.UP3!$B$5:$T$5,0),FALSE) -> 631 | H22: =VLOOKUP($B$22,'R.UP3'!$B$4:$S$54,MATCH(DETAIL!$F$4,'R.UP3'!$B$5:$S$5,0),FALSE) -> 498 | I22: =IF(OR(G22="N/A",H22="N/A"),"N/A",IF(AND(G22=0,H22=0),0,H22/G22*100)) -> 78.922345 | J22: =IF(OR(I22="N/A",I22<0),0,IF(I22>110,F22*110/100,F22*I22/100)) -> 1.5784469 | L22: =IF(N22="N/A",0,T.UP3!$F$37) -> 2 | M22: =VLOOKUP($B$22,T.UP3!$B$4:$T$69,MATCH(DETAIL!$L$4,T.UP3!$B$5:$T$5,0),FALSE) -> 1283 | N22: =VLOOKUP($B$22,'R.UP3'!$B$4:$S$54,MATCH(DETAIL!$L$4,'R.UP3'!$B$5:$S$5,0),FALSE) -> 965 | O22: =IF(OR(M22="N/A",N22="N/A"),"N/A",IF(AND(M22=0,N22=0),0,N22/M22*100)) -> 75.214341 | P22: =IF(OR(O22="N/A",O22<0),0,IF(O22>110,L22*110/100,L22*O22/100)) -> 1.5042868 | R22: =IF(T22="N/A",0,T.UP3!$F$37) -> 2 | S22: =VLOOKUP($B$22,T.UP3!$B$4:$T$69,MATCH(DETAIL!$R$4,T.UP3!$B$5:$T$5,0),FALSE) -> 1968 | T22: =VLOOKUP($B$22,'R.UP3'!$B$4:$S$54,MATCH(DETAIL!$R$4,'R.UP3'!$B$5:$S$5,0),FALSE) -> 1364 | U22: =IF(OR(S22="N/A",T22="N/A"),"N/A",IF(AND(S22=0,T22=0),0,T22/S22*100)) -> 69.308943 | V22: =IF(OR(U22="N/A",U22<0),0,IF(U22>110,R22*110/100,R22*U22/100)) -> 1.3861789 | X22: =IF(Z22="N/A",0,T.UP3!$F$37) -> #N/A | Y22: =VLOOKUP($B$22,T.UP3!$B$4:$T$69,MATCH(DETAIL!$X$4,T.UP3!$B$5:$T$5,0),FALSE) -> #N/A | Z22: =VLOOKUP($B$22,'R.UP3'!$B$4:$S$54,MATCH(DETAIL!$X$4,'R.UP3'!$B$5:$S$5,0),FALSE) -> #N/A | AA22: =IF(OR(Y22="N/A",Z22="N/A"),"N/A",IF(AND(Y22=0,Z22=0),0,Z22/Y22*100)) -> #N/A | AB22: =IF(OR(AA22="N/A",AA22<0),0,IF(AA22>110,X22*110/100,X22*AA22/100)) -> #N/A | AD22: =IF(AF22="N/A",0,T.UP3!$F$37) -> #N/A | AE22: =VLOOKUP($B$22,T.UP3!$B$4:$T$69,MATCH(DETAIL!$AD$4,T.UP3!$B$5:$T$5,0),FALSE) -> #N/A | AF22: =VLOOKUP($B$22,'R.UP3'!$B$4:$S$54,MATCH(DETAIL!$AD$4,'R.UP3'!$B$5:$S$5,0),FALSE) -> #N/A | AG22: =IF(OR(AE22="N/A",AF22="N/A"),"N/A",IF(AND(AE22=0,AF22=0),0,AF22/AE22*100)) -> #N/A | AH22: =IF(OR(AG22="N/A",AG22<0),0,IF(AG22>110,AD22*110/100,AD22*AG22/100)) -> #N/A
A23: =T.UP3!A40 -> 0 | B23: =T.UP3!B40 -> e. Penambahan Jumlah Pelanggan Rumah Tangga Lisdes | C23: =T.UP3!C40 -> ñ | D23: =T.UP3!D40 -> Pelanggan | F23: =IF(H23="N/A",0,T.UP3!$F$40) -> 1.5 | G23: =VLOOKUP($B$23,T.UP3!$B$4:$T$69,MATCH(DETAIL!$F$4,T.UP3!$B$5:$T$5,0),FALSE) -> 3 | H23: =VLOOKUP($B$23,'R.UP3'!$B$4:$S$54,MATCH(DETAIL!$F$4,'R.UP3'!$B$5:$S$5,0),FALSE) -> 50 | I23: =IF(OR(G23="N/A",H23="N/A"),"N/A",IF(AND(G23=0,H23=0),0,H23/G23*100)) -> 1666.6667 | J23: =IF(OR(I23="N/A",I23<0),0,IF(I23>110,F23*110/100,F23*I23/100)) -> 1.65 | L23: =IF(N23="N/A",0,T.UP3!$F$40) -> 1.5 | M23: =VLOOKUP($B$23,T.UP3!$B$4:$T$69,MATCH(DETAIL!$L$4,T.UP3!$B$5:$T$5,0),FALSE) -> 4 | N23: =VLOOKUP($B$23,'R.UP3'!$B$4:$S$54,MATCH(DETAIL!$L$4,'R.UP3'!$B$5:$S$5,0),FALSE) -> 71 | O23: =IF(OR(M23="N/A",N23="N/A"),"N/A",IF(AND(M23=0,N23=0),0,N23/M23*100)) -> 1775 | P23: =IF(OR(O23="N/A",O23<0),0,IF(O23>110,L23*110/100,L23*O23/100)) -> 1.65 | R23: =IF(T23="N/A",0,T.UP3!$F$40) -> 1.5 | S23: =VLOOKUP($B$23,T.UP3!$B$4:$T$69,MATCH(DETAIL!$R$4,T.UP3!$B$5:$T$5,0),FALSE) -> 4 | T23: =VLOOKUP($B$23,'R.UP3'!$B$4:$S$54,MATCH(DETAIL!$R$4,'R.UP3'!$B$5:$S$5,0),FALSE) -> 87 | U23: =IF(OR(S23="N/A",T23="N/A"),"N/A",IF(AND(S23=0,T23=0),0,T23/S23*100)) -> 2175 | V23: =IF(OR(U23="N/A",U23<0),0,IF(U23>110,R23*110/100,R23*U23/100)) -> 1.65 | X23: =IF(Z23="N/A",0,T.UP3!$F$40) -> #N/A | Y23: =VLOOKUP($B$23,T.UP3!$B$4:$T$69,MATCH(DETAIL!$X$4,T.UP3!$B$5:$T$5,0),FALSE) -> #N/A | Z23: =VLOOKUP($B$23,'R.UP3'!$B$4:$S$54,MATCH(DETAIL!$X$4,'R.UP3'!$B$5:$S$5,0),FALSE) -> #N/A | AA23: =IF(OR(Y23="N/A",Z23="N/A"),"N/A",IF(AND(Y23=0,Z23=0),0,Z23/Y23*100)) -> #N/A | AB23: =IF(OR(AA23="N/A",AA23<0),0,IF(AA23>110,X23*110/100,X23*AA23/100)) -> #N/A | AD23: =IF(AF23="N/A",0,T.UP3!$F$40) -> #N/A | AE23: =VLOOKUP($B$23,T.UP3!$B$4:$T$69,MATCH(DETAIL!$AD$4,T.UP3!$B$5:$T$5,0),FALSE) -> #N/A | AF23: =VLOOKUP($B$23,'R.UP3'!$B$4:$S$54,MATCH(DETAIL!$AD$4,'R.UP3'!$B$5:$S$5,0),FALSE) -> #N/A | AG23: =IF(OR(AE23="N/A",AF23="N/A"),"N/A",IF(AND(AE23=0,AF23=0),0,AF23/AE23*100)) -> #N/A | AH23: =IF(OR(AG23="N/A",AG23<0),0,IF(AG23>110,AD23*110/100,AD23*AG23/100)) -> #N/A
A24: =T.UP3!A42 -> 10 | B24: =T.UP3!B42 -> Pengelolaan Pembacaan Meter | C24: =T.UP3!C42 -> 0 | D24: =T.UP3!D42 -> 0 | F24: =IF(H24="N/A",0,T.UP3!$F$42) -> 4 | G24: =VLOOKUP($B$24,T.UP3!$B$4:$T$69,MATCH(DETAIL!$F$4,T.UP3!$B$5:$T$5,0),FALSE) -> 0 | H24: =VLOOKUP($B$24,'R.UP3'!$B$4:$S$54,MATCH(DETAIL!$F$4,'R.UP3'!$B$5:$S$5,0),FALSE) -> 0 | I24: =IF(OR(G24="N/A",H24="N/A"),"N/A",IF(AND(G24=0,H24=0),0,H24/G24*100)) -> 0 | J24: =IF(OR(I24="N/A",I24<0),0,IF(I24>110,F24*110/100,F24*I24/100)) -> 0 | L24: =IF(N24="N/A",0,T.UP3!$F$42) -> 4 | M24: =VLOOKUP($B$24,T.UP3!$B$4:$T$69,MATCH(DETAIL!$L$4,T.UP3!$B$5:$T$5,0),FALSE) -> 0 | N24: =VLOOKUP($B$24,'R.UP3'!$B$4:$S$54,MATCH(DETAIL!$L$4,'R.UP3'!$B$5:$S$5,0),FALSE) -> 0 | O24: =IF(OR(M24="N/A",N24="N/A"),"N/A",IF(AND(M24=0,N24=0),0,N24/M24*100)) -> 0 | P24: =IF(OR(O24="N/A",O24<0),0,IF(O24>110,L24*110/100,L24*O24/100)) -> 0 | R24: =IF(T24="N/A",0,T.UP3!$F$42) -> 4 | S24: =VLOOKUP($B$24,T.UP3!$B$4:$T$69,MATCH(DETAIL!$R$4,T.UP3!$B$5:$T$5,0),FALSE) -> 0 | T24: =VLOOKUP($B$24,'R.UP3'!$B$4:$S$54,MATCH(DETAIL!$R$4,'R.UP3'!$B$5:$S$5,0),FALSE) -> 0 | U24: =IF(OR(S24="N/A",T24="N/A"),"N/A",IF(AND(S24=0,T24=0),0,T24/S24*100)) -> 0 | V24: =IF(OR(U24="N/A",U24<0),0,IF(U24>110,R24*110/100,R24*U24/100)) -> 0 | X24: =IF(Z24="N/A",0,T.UP3!$F$42) -> #N/A | Y24: =VLOOKUP($B$24,T.UP3!$B$4:$T$69,MATCH(DETAIL!$X$4,T.UP3!$B$5:$T$5,0),FALSE) -> #N/A | Z24: =VLOOKUP($B$24,'R.UP3'!$B$4:$S$54,MATCH(DETAIL!$X$4,'R.UP3'!$B$5:$S$5,0),FALSE) -> #N/A | AA24: =IF(OR(Y24="N/A",Z24="N/A"),"N/A",IF(AND(Y24=0,Z24=0),0,Z24/Y24*100)) -> #N/A | AB24: =IF(OR(AA24="N/A",AA24<0),0,IF(AA24>110,X24*110/100,X24*AA24/100)) -> #N/A | AD24: =IF(AF24="N/A",0,T.UP3!$F$42) -> #N/A | AE24: =VLOOKUP($B$24,T.UP3!$B$4:$T$69,MATCH(DETAIL!$AD$4,T.UP3!$B$5:$T$5,0),FALSE) -> #N/A | AF24: =VLOOKUP($B$24,'R.UP3'!$B$4:$S$54,MATCH(DETAIL!$AD$4,'R.UP3'!$B$5:$S$5,0),FALSE) -> #N/A | AG24: =IF(OR(AE24="N/A",AF24="N/A"),"N/A",IF(AND(AE24=0,AF24=0),0,AF24/AE24*100)) -> #N/A | AH24: =IF(OR(AG24="N/A",AG24<0),0,IF(AG24>110,AD24*110/100,AD24*AG24/100)) -> #N/A
A25: =T.UP3!A43 -> 0 | B25: =T.UP3!B43 -> a. Jumlah Pengguna Swa Cam
B26: =T.UP3!#REF! -> #REF! | C26: =T.UP3!#REF! -> #REF! | D26: =T.UP3!#REF! -> #REF! | F26: =IF(H26="N/A",0,T.UP3!#REF!) -> #REF! | G26: =VLOOKUP($B$26,T.UP3!$B$4:$T$69,MATCH(DETAIL!$F$4,T.UP3!$B$5:$T$5,0),FALSE) -> #REF! | H26: =VLOOKUP($B$26,'R.UP3'!$B$4:$S$54,MATCH(DETAIL!$F$4,'R.UP3'!$B$5:$S$5,0),FALSE) -> #REF! | I26: =IF(OR(G26="N/A",H26="N/A"),"N/A",IF(AND(G26=0,H26=0),0,H26/G26*100)) -> #REF! | J26: =IF(OR(I26="N/A",I26<0),0,IF(I26>110,F26*110/100,F26*I26/100)) -> #REF! | L26: =IF(N26="N/A",0,T.UP3!#REF!) -> #REF! | M26: =VLOOKUP($B$26,T.UP3!$B$4:$T$69,MATCH(DETAIL!$L$4,T.UP3!$B$5:$T$5,0),FALSE) -> #REF! | N26: =VLOOKUP($B$26,'R.UP3'!$B$4:$S$54,MATCH(DETAIL!$L$4,'R.UP3'!$B$5:$S$5,0),FALSE) -> #REF! | O26: =IF(OR(M26="N/A",N26="N/A"),"N/A",IF(AND(M26=0,N26=0),0,N26/M26*100)) -> #REF! | P26: =IF(OR(O26="N/A",O26<0),0,IF(O26>110,L26*110/100,L26*O26/100)) -> #REF! | R26: =IF(T26="N/A",0,T.UP3!#REF!) -> #REF! | S26: =VLOOKUP($B$26,T.UP3!$B$4:$T$69,MATCH(DETAIL!$R$4,T.UP3!$B$5:$T$5,0),FALSE) -> #REF! | T26: =VLOOKUP($B$26,'R.UP3'!$B$4:$S$54,MATCH(DETAIL!$R$4,'R.UP3'!$B$5:$S$5,0),FALSE) -> #REF! | U26: =IF(OR(S26="N/A",T26="N/A"),"N/A",IF(AND(S26=0,T26=0),0,T26/S26*100)) -> #REF! | V26: =IF(OR(U26="N/A",U26<0),0,IF(U26>110,R26*110/100,R26*U26/100)) -> #REF! | X26: =IF(Z26="N/A",0,T.UP3!#REF!) -> #REF! | Y26: =VLOOKUP($B$26,T.UP3!$B$4:$T$69,MATCH(DETAIL!$X$4,T.UP3!$B$5:$T$5,0),FALSE) -> #REF! | Z26: =VLOOKUP($B$26,'R.UP3'!$B$4:$S$54,MATCH(DETAIL!$X$4,'R.UP3'!$B$5:$S$5,0),FALSE) -> #REF! | AA26: =IF(OR(Y26="N/A",Z26="N/A"),"N/A",IF(AND(Y26=0,Z26=0),0,Z26/Y26*100)) -> #REF! | AB26: =IF(OR(AA26="N/A",AA26<0),0,IF(AA26>110,X26*110/100,X26*AA26/100)) -> #REF! | AD26: =IF(AF26="N/A",0,T.UP3!#REF!) -> #REF! | AE26: =VLOOKUP($B$26,T.UP3!$B$4:$T$69,MATCH(DETAIL!$AD$4,T.UP3!$B$5:$T$5,0),FALSE) -> #REF! | AF26: =VLOOKUP($B$26,'R.UP3'!$B$4:$S$54,MATCH(DETAIL!$AD$4,'R.UP3'!$B$5:$S$5,0),FALSE) -> #REF! | AG26: =IF(OR(AE26="N/A",AF26="N/A"),"N/A",IF(AND(AE26=0,AF26=0),0,AF26/AE26*100)) -> #REF! | AH26: =IF(OR(AG26="N/A",AG26<0),0,IF(AG26>110,AD26*110/100,AD26*AG26/100)) -> #REF!
B27: =T.UP3!B46 -> a. Pencapaian Rata-Rata Saldo Tanggal 20 diluar Konsumen Instansi (Kementerian & Lembaga)
B28: =T.UP3!B50 -> a. Pengendalian Penggunaan Anggaran Investasi sesuai RKAP | C28: =T.UP3!C50 -> ó | D28: =T.UP3!D50 -> % | F28: =IF(H28="N/A",0,T.UP3!$F$50) -> 0 | G28: =VLOOKUP($B$28,T.UP3!$B$4:$T$69,MATCH(DETAIL!$F$4,T.UP3!$B$5:$T$5,0),FALSE) -> 95-100 | H28: =VLOOKUP($B$28,'R.UP3'!$B$4:$S$54,MATCH(DETAIL!$F$4,'R.UP3'!$B$5:$S$5,0),FALSE) -> 100 | I28: =IF(OR(G28="N/A",H28="N/A"),"N/A",IF(AND(G28=0,H28=0),0,(2-H28/G28)*100)) -> #VALUE! | J28: =IF(OR(I28="N/A",I28<0),0,IF(I28>110,F28*110/100,F28*I28/100)) -> #VALUE! | L28: =IF(N28="N/A",0,T.UP3!$F$50) -> 0 | M28: =VLOOKUP($B$28,T.UP3!$B$4:$T$69,MATCH(DETAIL!$L$4,T.UP3!$B$5:$T$5,0),FALSE) -> 95-100 | N28: =VLOOKUP($B$28,'R.UP3'!$B$4:$S$54,MATCH(DETAIL!$L$4,'R.UP3'!$B$5:$S$5,0),FALSE) -> 100 | O28: =IF(OR(M28="N/A",N28="N/A"),"N/A",IF(AND(M28=0,N28=0),0,(2-N28/M28)*100)) -> #VALUE! | P28: =IF(OR(O28="N/A",O28<0),0,IF(O28>110,L28*110/100,L28*O28/100)) -> #VALUE! | R28: =IF(T28="N/A",0,T.UP3!$F$50) -> 0 | S28: =VLOOKUP($B$28,T.UP3!$B$4:$T$69,MATCH(DETAIL!$R$4,T.UP3!$B$5:$T$5,0),FALSE) -> 95-100 | T28: =VLOOKUP($B$28,'R.UP3'!$B$4:$S$54,MATCH(DETAIL!$R$4,'R.UP3'!$B$5:$S$5,0),FALSE) -> 39.55 | U28: =IF(OR(S28="N/A",T28="N/A"),"N/A",IF(AND(S28=0,T28=0),0,(2-T28/S28)*100)) -> #VALUE! | V28: =IF(OR(U28="N/A",U28<0),0,IF(U28>110,R28*110/100,R28*U28/100)) -> #VALUE! | X28: =IF(Z28="N/A",0,T.UP3!$F$50) -> #N/A | Y28: =VLOOKUP($B$28,T.UP3!$B$4:$T$69,MATCH(DETAIL!$X$4,T.UP3!$B$5:$T$5,0),FALSE) -> #N/A | Z28: =VLOOKUP($B$28,'R.UP3'!$B$4:$S$54,MATCH(DETAIL!$X$4,'R.UP3'!$B$5:$S$5,0),FALSE) -> #N/A | AA28: =IF(OR(Y28="N/A",Z28="N/A"),"N/A",IF(AND(Y28=0,Z28=0),0,(2-Z28/Y28)*100)) -> #N/A | AB28: =IF(OR(AA28="N/A",AA28<0),0,IF(AA28>110,X28*110/100,X28*AA28/100)) -> #N/A | AD28: =IF(AF28="N/A",0,T.UP3!$F$50) -> #N/A | AE28: =VLOOKUP($B$28,T.UP3!$B$4:$T$69,MATCH(DETAIL!$AD$4,T.UP3!$B$5:$T$5,0),FALSE) -> #N/A | AF28: =VLOOKUP($B$28,'R.UP3'!$B$4:$S$54,MATCH(DETAIL!$AD$4,'R.UP3'!$B$5:$S$5,0),FALSE) -> #N/A | AG28: =IF(OR(AE28="N/A",AF28="N/A"),"N/A",IF(AND(AE28=0,AF28=0),0,(2-AF28/AE28)*100)) -> #N/A | AH28: =IF(OR(AG28="N/A",AG28<0),0,IF(AG28>110,AD28*110/100,AD28*AG28/100)) -> #N/A
B29: =T.UP3!#REF! -> #REF! | C29: =T.UP3!#REF! -> #REF! | D29: =T.UP3!#REF! -> #REF! | F29: =IF(H29="N/A",0,T.UP3!#REF!) -> #REF! | G29: =VLOOKUP($B$29,T.UP3!$B$4:$T$69,MATCH(DETAIL!$F$4,T.UP3!$B$5:$T$5,0),FALSE) -> #REF! | H29: =VLOOKUP($B$29,'R.UP3'!$B$4:$S$54,MATCH(DETAIL!$F$4,'R.UP3'!$B$5:$S$5,0),FALSE) -> #REF! | I29: =IF(OR(G29="N/A",H29="N/A"),"N/A",IF(AND(G29=0,H29=0),0,(2-H29/G29)*100)) -> #REF! | J29: =IF(OR(I29="N/A",I29<0),0,IF(I29>110,F29*110/100,F29*I29/100)) -> #REF! | L29: =IF(N29="N/A",0,T.UP3!#REF!) -> #REF! | M29: =VLOOKUP($B$29,T.UP3!$B$4:$T$69,MATCH(DETAIL!$L$4,T.UP3!$B$5:$T$5,0),FALSE) -> #REF! | N29: =VLOOKUP($B$29,'R.UP3'!$B$4:$S$54,MATCH(DETAIL!$L$4,'R.UP3'!$B$5:$S$5,0),FALSE) -> #REF! | O29: =IF(OR(M29="N/A",N29="N/A"),"N/A",IF(AND(M29=0,N29=0),0,(2-N29/M29)*100)) -> #REF! | P29: =IF(OR(O29="N/A",O29<0),0,IF(O29>110,L29*110/100,L29*O29/100)) -> #REF! | R29: =IF(T29="N/A",0,T.UP3!#REF!) -> #REF! | S29: =VLOOKUP($B$29,T.UP3!$B$4:$T$69,MATCH(DETAIL!$R$4,T.UP3!$B$5:$T$5,0),FALSE) -> #REF! | T29: =VLOOKUP($B$29,'R.UP3'!$B$4:$S$54,MATCH(DETAIL!$R$4,'R.UP3'!$B$5:$S$5,0),FALSE) -> #REF! | U29: =IF(OR(S29="N/A",T29="N/A"),"N/A",IF(AND(S29=0,T29=0),0,(2-T29/S29)*100)) -> #REF! | V29: =IF(OR(U29="N/A",U29<0),0,IF(U29>110,R29*110/100,R29*U29/100)) -> #REF! | X29: =IF(Z29="N/A",0,T.UP3!#REF!) -> #REF! | Y29: =VLOOKUP($B$29,T.UP3!$B$4:$T$69,MATCH(DETAIL!$X$4,T.UP3!$B$5:$T$5,0),FALSE) -> #REF! | Z29: =VLOOKUP($B$29,'R.UP3'!$B$4:$S$54,MATCH(DETAIL!$X$4,'R.UP3'!$B$5:$S$5,0),FALSE) -> #REF! | AA29: =IF(OR(Y29="N/A",Z29="N/A"),"N/A",IF(AND(Y29=0,Z29=0),0,(2-Z29/Y29)*100)) -> #REF! | AB29: =IF(OR(AA29="N/A",AA29<0),0,IF(AA29>110,X29*110/100,X29*AA29/100)) -> #REF! | AD29: =IF(AF29="N/A",0,T.UP3!#REF!) -> #REF! | AE29: =VLOOKUP($B$29,T.UP3!$B$4:$T$69,MATCH(DETAIL!$AD$4,T.UP3!$B$5:$T$5,0),FALSE) -> #REF! | AF29: =VLOOKUP($B$29,'R.UP3'!$B$4:$S$54,MATCH(DETAIL!$AD$4,'R.UP3'!$B$5:$S$5,0),FALSE) -> #REF! | AG29: =IF(OR(AE29="N/A",AF29="N/A"),"N/A",IF(AND(AE29=0,AF29=0),0,(2-AF29/AE29)*100)) -> #REF! | AH29: =IF(OR(AG29="N/A",AG29<0),0,IF(AG29>110,AD29*110/100,AD29*AG29/100)) -> #REF!
B30: =T.UP3!#REF! -> #REF! | C30: =T.UP3!#REF! -> #REF! | D30: =T.UP3!#REF! -> #REF! | F30: =IF(H30="N/A",0,T.UP3!#REF!) -> #REF! | G30: =VLOOKUP($B$30,T.UP3!$B$4:$T$69,MATCH(DETAIL!$F$4,T.UP3!$B$5:$T$5,0),FALSE) -> #REF! | H30: =VLOOKUP($B$30,'R.UP3'!$B$4:$S$54,MATCH(DETAIL!$F$4,'R.UP3'!$B$5:$S$5,0),FALSE) -> #REF! | I30: =IF(OR(G30="N/A",H30="N/A"),"N/A",IF(AND(G30=0,H30=0),0,(2-H30/G30)*100)) -> #REF! | J30: =IF(OR(I30="N/A",I30<0),0,IF(I30>110,F30*110/100,F30*I30/100)) -> #REF! | L30: =IF(N30="N/A",0,T.UP3!#REF!) -> #REF! | M30: =VLOOKUP($B$30,T.UP3!$B$4:$T$69,MATCH(DETAIL!$L$4,T.UP3!$B$5:$T$5,0),FALSE) -> #REF! | N30: =VLOOKUP($B$30,'R.UP3'!$B$4:$S$54,MATCH(DETAIL!$L$4,'R.UP3'!$B$5:$S$5,0),FALSE) -> #REF! | O30: =IF(OR(M30="N/A",N30="N/A"),"N/A",IF(AND(M30=0,N30=0),0,(2-N30/M30)*100)) -> #REF! | P30: =IF(OR(O30="N/A",O30<0),0,IF(O30>110,L30*110/100,L30*O30/100)) -> #REF! | R30: =IF(T30="N/A",0,T.UP3!#REF!) -> #REF! | S30: =VLOOKUP($B$30,T.UP3!$B$4:$T$69,MATCH(DETAIL!$R$4,T.UP3!$B$5:$T$5,0),FALSE) -> #REF! | T30: =VLOOKUP($B$30,'R.UP3'!$B$4:$S$54,MATCH(DETAIL!$R$4,'R.UP3'!$B$5:$S$5,0),FALSE) -> #REF! | U30: =IF(OR(S30="N/A",T30="N/A"),"N/A",IF(AND(S30=0,T30=0),0,(2-T30/S30)*100)) -> #REF! | V30: =IF(OR(U30="N/A",U30<0),0,IF(U30>110,R30*110/100,R30*U30/100)) -> #REF! | X30: =IF(Z30="N/A",0,T.UP3!#REF!) -> #REF! | Y30: =VLOOKUP($B$30,T.UP3!$B$4:$T$69,MATCH(DETAIL!$X$4,T.UP3!$B$5:$T$5,0),FALSE) -> #REF! | Z30: =VLOOKUP($B$30,'R.UP3'!$B$4:$S$54,MATCH(DETAIL!$X$4,'R.UP3'!$B$5:$S$5,0),FALSE) -> #REF! | AA30: =IF(OR(Y30="N/A",Z30="N/A"),"N/A",IF(AND(Y30=0,Z30=0),0,(2-Z30/Y30)*100)) -> #REF! | AB30: =IF(OR(AA30="N/A",AA30<0),0,IF(AA30>110,X30*110/100,X30*AA30/100)) -> #REF! | AD30: =IF(AF30="N/A",0,T.UP3!#REF!) -> #REF! | AE30: =VLOOKUP($B$30,T.UP3!$B$4:$T$69,MATCH(DETAIL!$AD$4,T.UP3!$B$5:$T$5,0),FALSE) -> #REF! | AF30: =VLOOKUP($B$30,'R.UP3'!$B$4:$S$54,MATCH(DETAIL!$AD$4,'R.UP3'!$B$5:$S$5,0),FALSE) -> #REF! | AG30: =IF(OR(AE30="N/A",AF30="N/A"),"N/A",IF(AND(AE30=0,AF30=0),0,(2-AF30/AE30)*100)) -> #REF! | AH30: =IF(OR(AG30="N/A",AG30<0),0,IF(AG30>110,AD30*110/100,AD30*AG30/100)) -> #REF!
B31: =T.UP3!#REF! -> #REF! | C31: =T.UP3!#REF! -> #REF! | D31: =T.UP3!#REF! -> #REF! | F31: =IF(H31="N/A",0,T.UP3!#REF!) -> #REF! | G31: =VLOOKUP($B$31,T.UP3!$B$4:$T$69,MATCH(DETAIL!$F$4,T.UP3!$B$5:$T$5,0),FALSE) -> #REF! | H31: =VLOOKUP($B$31,'R.UP3'!$B$4:$S$54,MATCH(DETAIL!$F$4,'R.UP3'!$B$5:$S$5,0),FALSE) -> #REF! | I31: =IF(OR(G31="N/A",H31="N/A"),"N/A",IF(AND(G31=0,H31=0),0,H31/G31*100)) -> #REF! | J31: =IF(OR(I31="N/A",I31<0),0,IF(I31>110,F31*110/100,F31*I31/100)) -> #REF! | L31: =IF(N31="N/A",0,T.UP3!#REF!) -> #REF! | M31: =VLOOKUP($B$31,T.UP3!$B$4:$T$69,MATCH(DETAIL!$L$4,T.UP3!$B$5:$T$5,0),FALSE) -> #REF! | N31: =VLOOKUP($B$31,'R.UP3'!$B$4:$S$54,MATCH(DETAIL!$L$4,'R.UP3'!$B$5:$S$5,0),FALSE) -> #REF! | O31: =IF(OR(M31="N/A",N31="N/A"),"N/A",IF(AND(M31=0,N31=0),0,N31/M31*100)) -> #REF! | P31: =IF(OR(O31="N/A",O31<0),0,IF(O31>110,L31*110/100,L31*O31/100)) -> #REF! | R31: =IF(T31="N/A",0,T.UP3!#REF!) -> #REF! | S31: =VLOOKUP($B$31,T.UP3!$B$4:$T$69,MATCH(DETAIL!$R$4,T.UP3!$B$5:$T$5,0),FALSE) -> #REF! | T31: =VLOOKUP($B$31,'R.UP3'!$B$4:$S$54,MATCH(DETAIL!$R$4,'R.UP3'!$B$5:$S$5,0),FALSE) -> #REF! | U31: =IF(OR(S31="N/A",T31="N/A"),"N/A",IF(AND(S31=0,T31=0),0,T31/S31*100)) -> #REF! | V31: =IF(OR(U31="N/A",U31<0),0,IF(U31>110,R31*110/100,R31*U31/100)) -> #REF! | X31: =IF(Z31="N/A",0,T.UP3!#REF!) -> #REF! | Y31: =VLOOKUP($B$31,T.UP3!$B$4:$T$69,MATCH(DETAIL!$X$4,T.UP3!$B$5:$T$5,0),FALSE) -> #REF! | Z31: =VLOOKUP($B$31,'R.UP3'!$B$4:$S$54,MATCH(DETAIL!$X$4,'R.UP3'!$B$5:$S$5,0),FALSE) -> #REF! | AA31: =IF(OR(Y31="N/A",Z31="N/A"),"N/A",IF(AND(Y31=0,Z31=0),0,Z31/Y31*100)) -> #REF! | AB31: =IF(OR(AA31="N/A",AA31<0),0,IF(AA31>110,X31*110/100,X31*AA31/100)) -> #REF! | AD31: =IF(AF31="N/A",0,T.UP3!#REF!) -> #REF! | AE31: =VLOOKUP($B$31,T.UP3!$B$4:$T$69,MATCH(DETAIL!$AD$4,T.UP3!$B$5:$T$5,0),FALSE) -> #REF! | AF31: =VLOOKUP($B$31,'R.UP3'!$B$4:$S$54,MATCH(DETAIL!$AD$4,'R.UP3'!$B$5:$S$5,0),FALSE) -> #REF! | AG31: =IF(OR(AE31="N/A",AF31="N/A"),"N/A",IF(AND(AE31=0,AF31=0),0,AF31/AE31*100)) -> #REF! | AH31: =IF(OR(AG31="N/A",AG31<0),0,IF(AG31>110,AD31*110/100,AD31*AG31/100)) -> #REF!
B32: =T.UP3!B51 -> b. Usulan Penghapusan ATTB | C32: =T.UP3!C51 -> ñ | D32: =T.UP3!D51 -> Rp. Milyar | F32: =IF(H32="N/A",0,T.UP3!$F$51) -> 0 | G32: =VLOOKUP($B$32,T.UP3!$B$4:$T$69,MATCH(DETAIL!$F$4,T.UP3!$B$5:$T$5,0),FALSE) -> 0 | H32: =VLOOKUP($B$32,'R.UP3'!$B$4:$S$54,MATCH(DETAIL!$F$4,'R.UP3'!$B$5:$S$5,0),FALSE) -> 0 | I32: =IF(OR(G32="N/A",H32="N/A"),"N/A",IF(AND(G32=0,H32=0),0,H32/G32*100)) -> 0 | J32: =IF(OR(I32="N/A",I32<0),0,IF(I32>110,F32*110/100,F32*I32/100)) -> 0 | L32: =IF(N32="N/A",0,T.UP3!$F$51) -> 0 | M32: =VLOOKUP($B$32,T.UP3!$B$4:$T$69,MATCH(DETAIL!$L$4,T.UP3!$B$5:$T$5,0),FALSE) -> 0 | N32: =VLOOKUP($B$32,'R.UP3'!$B$4:$S$54,MATCH(DETAIL!$L$4,'R.UP3'!$B$5:$S$5,0),FALSE) -> 0 | O32: =IF(OR(M32="N/A",N32="N/A"),"N/A",IF(AND(M32=0,N32=0),0,N32/M32*100)) -> 0 | P32: =IF(OR(O32="N/A",O32<0),0,IF(O32>110,L32*110/100,L32*O32/100)) -> 0 | R32: =IF(T32="N/A",0,T.UP3!$F$51) -> 0 | S32: =VLOOKUP($B$32,T.UP3!$B$4:$T$69,MATCH(DETAIL!$R$4,T.UP3!$B$5:$T$5,0),FALSE) -> 0 | T32: =VLOOKUP($B$32,'R.UP3'!$B$4:$S$54,MATCH(DETAIL!$R$4,'R.UP3'!$B$5:$S$5,0),FALSE) -> 0 | U32: =IF(OR(S32="N/A",T32="N/A"),"N/A",IF(AND(S32=0,T32=0),0,T32/S32*100)) -> 0 | V32: =IF(OR(U32="N/A",U32<0),0,IF(U32>110,R32*110/100,R32*U32/100)) -> 0 | X32: =IF(Z32="N/A",0,T.UP3!$F$51) -> #N/A | Y32: =VLOOKUP($B$32,T.UP3!$B$4:$T$69,MATCH(DETAIL!$X$4,T.UP3!$B$5:$T$5,0),FALSE) -> #N/A | Z32: =VLOOKUP($B$32,'R.UP3'!$B$4:$S$54,MATCH(DETAIL!$X$4,'R.UP3'!$B$5:$S$5,0),FALSE) -> #N/A | AA32: =IF(OR(Y32="N/A",Z32="N/A"),"N/A",IF(AND(Y32=0,Z32=0),0,Z32/Y32*100)) -> #N/A | AB32: =IF(OR(AA32="N/A",AA32<0),0,IF(AA32>110,X32*110/100,X32*AA32/100)) -> #N/A | AD32: =IF(AF32="N/A",0,T.UP3!$F$51) -> #N/A | AE32: =VLOOKUP($B$32,T.UP3!$B$4:$T$69,MATCH(DETAIL!$AD$4,T.UP3!$B$5:$T$5,0),FALSE) -> #N/A | AF32: =VLOOKUP($B$32,'R.UP3'!$B$4:$S$54,MATCH(DETAIL!$AD$4,'R.UP3'!$B$5:$S$5,0),FALSE) -> #N/A | AG32: =IF(OR(AE32="N/A",AF32="N/A"),"N/A",IF(AND(AE32=0,AF32=0),0,AF32/AE32*100)) -> #N/A | AH32: =IF(OR(AG32="N/A",AG32<0),0,IF(AG32>110,AD32*110/100,AD32*AG32/100)) -> #N/A
B33: =T.UP3!#REF! -> #REF! | C33: =T.UP3!#REF! -> #REF! | D33: =T.UP3!#REF! -> #REF! | F33: =IF(H33="N/A",0,T.UP3!#REF!) -> #REF! | G33: =VLOOKUP($B$33,T.UP3!$B$4:$T$69,MATCH(DETAIL!$F$4,T.UP3!$B$5:$T$5,0),FALSE) -> #REF! | H33: =VLOOKUP($B$33,'R.UP3'!$B$4:$S$54,MATCH(DETAIL!$F$4,'R.UP3'!$B$5:$S$5,0),FALSE) -> #REF! | I33: =IF(OR(G33="N/A",H33="N/A"),"N/A",IF(AND(G33=0,H33=0),0,H33/G33*100)) -> #REF! | J33: =IF(OR(I33="N/A",I33<0),0,IF(I33>110,F33*110/100,F33*I33/100)) -> #REF! | L33: =IF(N33="N/A",0,T.UP3!#REF!) -> #REF! | M33: =VLOOKUP($B$33,T.UP3!$B$4:$T$69,MATCH(DETAIL!$L$4,T.UP3!$B$5:$T$5,0),FALSE) -> #REF! | N33: =VLOOKUP($B$33,'R.UP3'!$B$4:$S$54,MATCH(DETAIL!$L$4,'R.UP3'!$B$5:$S$5,0),FALSE) -> #REF! | O33: =IF(OR(M33="N/A",N33="N/A"),"N/A",IF(AND(M33=0,N33=0),0,N33/M33*100)) -> #REF! | P33: =IF(OR(O33="N/A",O33<0),0,IF(O33>110,L33*110/100,L33*O33/100)) -> #REF! | R33: =IF(T33="N/A",0,T.UP3!#REF!) -> #REF! | S33: =VLOOKUP($B$33,T.UP3!$B$4:$T$69,MATCH(DETAIL!$R$4,T.UP3!$B$5:$T$5,0),FALSE) -> #REF! | T33: =VLOOKUP($B$33,'R.UP3'!$B$4:$S$54,MATCH(DETAIL!$R$4,'R.UP3'!$B$5:$S$5,0),FALSE) -> #REF! | U33: =IF(OR(S33="N/A",T33="N/A"),"N/A",IF(AND(S33=0,T33=0),0,T33/S33*100)) -> #REF! | V33: =IF(OR(U33="N/A",U33<0),0,IF(U33>110,R33*110/100,R33*U33/100)) -> #REF! | X33: =IF(Z33="N/A",0,T.UP3!#REF!) -> #REF! | Y33: =VLOOKUP($B$33,T.UP3!$B$4:$T$69,MATCH(DETAIL!$X$4,T.UP3!$B$5:$T$5,0),FALSE) -> #REF! | Z33: =VLOOKUP($B$33,'R.UP3'!$B$4:$S$54,MATCH(DETAIL!$X$4,'R.UP3'!$B$5:$S$5,0),FALSE) -> #REF! | AA33: =IF(OR(Y33="N/A",Z33="N/A"),"N/A",IF(AND(Y33=0,Z33=0),0,Z33/Y33*100)) -> #REF! | AB33: =IF(OR(AA33="N/A",AA33<0),0,IF(AA33>110,X33*110/100,X33*AA33/100)) -> #REF! | AD33: =IF(AF33="N/A",0,T.UP3!#REF!) -> #REF! | AE33: =VLOOKUP($B$33,T.UP3!$B$4:$T$69,MATCH(DETAIL!$AD$4,T.UP3!$B$5:$T$5,0),FALSE) -> #REF! | AF33: =VLOOKUP($B$33,'R.UP3'!$B$4:$S$54,MATCH(DETAIL!$AD$4,'R.UP3'!$B$5:$S$5,0),FALSE) -> #REF! | AG33: =IF(OR(AE33="N/A",AF33="N/A"),"N/A",IF(AND(AE33=0,AF33=0),0,AF33/AE33*100)) -> #REF! | AH33: =IF(OR(AG33="N/A",AG33<0),0,IF(AG33>110,AD33*110/100,AD33*AG33/100)) -> #REF!
A34: =T.UP3!A52 -> 0 | B34: =T.UP3!B52 -> c. Usulan Penghapusan PRR
B35: =T.UP3!B54 -> a. HCR, OCR, dan Produktivitas Pegawai | C35: =T.UP3!C54 -> ñ | D35: =T.UP3!D54 -> % | F35: =IF(H35="N/A",0,T.UP3!$F$54) -> 0 | G35: =VLOOKUP($B$35,T.UP3!$B$4:$T$69,MATCH(DETAIL!$F$4,T.UP3!$B$5:$T$5,0),FALSE) -> 0 | H35: =VLOOKUP($B$35,'R.UP3'!$B$4:$S$54,MATCH(DETAIL!$F$4,'R.UP3'!$B$5:$S$5,0),FALSE) -> 100 | I35: =IF(OR(G35="N/A",H35="N/A"),"N/A",IF(AND(G35=0,H35=0),0,H35/G35*100)) -> #DIV/0! | J35: =IF(OR(I35="N/A",I35<0),0,IF(I35>110,F35*110/100,F35*I35/100)) -> #DIV/0! | L35: =IF(N35="N/A",0,T.UP3!$F$54) -> 0 | M35: =VLOOKUP($B$35,T.UP3!$B$4:$T$69,MATCH(DETAIL!$L$4,T.UP3!$B$5:$T$5,0),FALSE) -> 0 | N35: =VLOOKUP($B$35,'R.UP3'!$B$4:$S$54,MATCH(DETAIL!$L$4,'R.UP3'!$B$5:$S$5,0),FALSE) -> 100 | O35: =IF(OR(M35="N/A",N35="N/A"),"N/A",IF(AND(M35=0,N35=0),0,N35/M35*100)) -> #DIV/0! | P35: =IF(OR(O35="N/A",O35<0),0,IF(O35>110,L35*110/100,L35*O35/100)) -> #DIV/0! | R35: =IF(T35="N/A",0,T.UP3!$F$54) -> 0 | S35: =VLOOKUP($B$35,T.UP3!$B$4:$T$69,MATCH(DETAIL!$R$4,T.UP3!$B$5:$T$5,0),FALSE) -> 0 | T35: =VLOOKUP($B$35,'R.UP3'!$B$4:$S$54,MATCH(DETAIL!$R$4,'R.UP3'!$B$5:$S$5,0),FALSE) -> 100 | U35: =IF(OR(S35="N/A",T35="N/A"),"N/A",IF(AND(S35=0,T35=0),0,T35/S35*100)) -> #DIV/0! | V35: =IF(OR(U35="N/A",U35<0),0,IF(U35>110,R35*110/100,R35*U35/100)) -> #DIV/0! | X35: =IF(Z35="N/A",0,T.UP3!$F$54) -> #N/A | Y35: =VLOOKUP($B$35,T.UP3!$B$4:$T$69,MATCH(DETAIL!$X$4,T.UP3!$B$5:$T$5,0),FALSE) -> #N/A | Z35: =VLOOKUP($B$35,'R.UP3'!$B$4:$S$54,MATCH(DETAIL!$X$4,'R.UP3'!$B$5:$S$5,0),FALSE) -> #N/A | AA35: =IF(OR(Y35="N/A",Z35="N/A"),"N/A",IF(AND(Y35=0,Z35=0),0,Z35/Y35*100)) -> #N/A | AB35: =IF(OR(AA35="N/A",AA35<0),0,IF(AA35>110,X35*110/100,X35*AA35/100)) -> #N/A | AD35: =IF(AF35="N/A",0,T.UP3!$F$54) -> #N/A | AE35: =VLOOKUP($B$35,T.UP3!$B$4:$T$69,MATCH(DETAIL!$AD$4,T.UP3!$B$5:$T$5,0),FALSE) -> #N/A | AF35: =VLOOKUP($B$35,'R.UP3'!$B$4:$S$54,MATCH(DETAIL!$AD$4,'R.UP3'!$B$5:$S$5,0),FALSE) -> #N/A | AG35: =IF(OR(AE35="N/A",AF35="N/A"),"N/A",IF(AND(AE35=0,AF35=0),0,AF35/AE35*100)) -> #N/A | AH35: =IF(OR(AG35="N/A",AG35<0),0,IF(AG35>110,AD35*110/100,AD35*AG35/100)) -> #N/A
